 * Serving Flask app "tommi.py"
 * Environment: production
   WARNING: Do not use the development server in a production environment.
   Use a production WSGI server instead.
 * Debug mode: off
 * Running on http://127.0.0.1:5000/ (Press CTRL+C to quit)
127.0.0.1 - - [02/Apr/2021 16:52:27] "GET /analise/foliosnames HTTP/1.1" 200 -
127.0.0.1 - - [02/Apr/2021 16:52:39] "OPTIONS /login HTTP/1.1" 200 -
127.0.0.1 - - [02/Apr/2021 16:52:39] "POST /login HTTP/1.1" 200 -
127.0.0.1 - - [02/Apr/2021 16:52:41] "POST /login HTTP/1.1" 200 -
 * Serving Flask app "tommi.py"
 * Environment: production
   WARNING: Do not use the development server in a production environment.
   Use a production WSGI server instead.
 * Debug mode: off
 * Running on http://127.0.0.1:5000/ (Press CTRL+C to quit)
127.0.0.1 - - [02/Apr/2021 17:31:56] "GET /analise/foliosnames HTTP/1.1" 200 -
127.0.0.1 - - [02/Apr/2021 17:32:05] "OPTIONS /login HTTP/1.1" 200 -
127.0.0.1 - - [02/Apr/2021 17:32:05] "POST /login HTTP/1.1" 200 -
127.0.0.1 - - [02/Apr/2021 17:32:10] "OPTIONS /users/users?nome=jna HTTP/1.1" 200 -
127.0.0.1 - - [02/Apr/2021 17:32:10] "OPTIONS /users/foto/jna?seed=1617381130017 HTTP/1.1" 200 -
127.0.0.1 - - [02/Apr/2021 17:32:10] "OPTIONS /folios/folios?nome=jna HTTP/1.1" 200 -
127.0.0.1 - - [02/Apr/2021 17:32:10] "GET /folios/folios?nome=jna HTTP/1.1" 200 -
127.0.0.1 - - [02/Apr/2021 17:32:10] "GET /users/users?nome=jna HTTP/1.1" 200 -
127.0.0.1 - - [02/Apr/2021 17:32:10] "OPTIONS /users/foto/jna HTTP/1.1" 200 -
127.0.0.1 - - [02/Apr/2021 17:32:10] "GET /users/foto/jna?seed=1617381130017 HTTP/1.1" 200 -
127.0.0.1 - - [02/Apr/2021 17:32:12] "OPTIONS /folios/tags?nome=jna HTTP/1.1" 200 -
127.0.0.1 - - [02/Apr/2021 17:32:12] "OPTIONS /folios/index?nome=jna HTTP/1.1" 200 -
127.0.0.1 - - [02/Apr/2021 17:32:12] "GET /folios/tags?nome=jna HTTP/1.1" 200 -
127.0.0.1 - - [02/Apr/2021 17:32:12] "GET /folios/index?nome=jna HTTP/1.1" 200 -
127.0.0.1 - - [02/Apr/2021 17:33:09] "OPTIONS /login HTTP/1.1" 200 -
127.0.0.1 - - [02/Apr/2021 17:33:09] "POST /login HTTP/1.1" 200 -
127.0.0.1 - - [02/Apr/2021 17:33:09] "OPTIONS /users/users?nome=jna HTTP/1.1" 200 -
127.0.0.1 - - [02/Apr/2021 17:33:09] "OPTIONS /folios/folios?nome=jna HTTP/1.1" 200 -
127.0.0.1 - - [02/Apr/2021 17:33:09] "OPTIONS /users/foto/jna?seed=1617381189660 HTTP/1.1" 200 -
127.0.0.1 - - [02/Apr/2021 17:33:09] "OPTIONS /users/foto/jna HTTP/1.1" 200 -
127.0.0.1 - - [02/Apr/2021 17:33:10] "GET /users/users?nome=jna HTTP/1.1" 200 -
127.0.0.1 - - [02/Apr/2021 17:33:10] "GET /folios/folios?nome=jna HTTP/1.1" 200 -
127.0.0.1 - - [02/Apr/2021 17:33:10] "GET /users/foto/jna?seed=1617381189660 HTTP/1.1" 200 -
127.0.0.1 - - [02/Apr/2021 17:33:10] "OPTIONS /folios/tags?nome=jna HTTP/1.1" 200 -
127.0.0.1 - - [02/Apr/2021 17:33:10] "OPTIONS /folios/index?nome=jna HTTP/1.1" 200 -
127.0.0.1 - - [02/Apr/2021 17:33:10] "GET /folios/tags?nome=jna HTTP/1.1" 200 -
127.0.0.1 - - [02/Apr/2021 17:33:11] "GET /folios/index?nome=jna HTTP/1.1" 200 -
127.0.0.1 - - [02/Apr/2021 22:26:38] "GET /analise/foliosnames HTTP/1.1" 200 -
127.0.0.1 - - [02/Apr/2021 22:26:49] "GET /analise/pesquisa?pesquisa=Braga&selectedFolio=Todos&tipo=texto&versao=todas&resultado=periodo HTTP/1.1" 200 -
127.0.0.1 - - [02/Apr/2021 22:26:52] "GET /analise/foliosnames HTTP/1.1" 200 -
127.0.0.1 - - [02/Apr/2021 22:42:09] "GET /analise/foliosnames HTTP/1.1" 200 -
127.0.0.1 - - [02/Apr/2021 22:42:14] "GET /analise/pesquisa?pesquisa=Braga&selectedFolio=Todos&tipo=texto&versao=todas&resultado=periodo HTTP/1.1" 200 -
127.0.0.1 - - [02/Apr/2021 22:42:22] "GET /analise/foliosnames HTTP/1.1" 200 -
127.0.0.1 - - [02/Apr/2021 22:42:35] "OPTIONS /login HTTP/1.1" 200 -
127.0.0.1 - - [02/Apr/2021 22:42:35] "POST /login HTTP/1.1" 200 -
127.0.0.1 - - [02/Apr/2021 22:42:42] "OPTIONS /login HTTP/1.1" 200 -
127.0.0.1 - - [02/Apr/2021 22:42:43] "POST /login HTTP/1.1" 200 -
127.0.0.1 - - [02/Apr/2021 22:42:43] "OPTIONS /users/users?nome=jna HTTP/1.1" 200 -
127.0.0.1 - - [02/Apr/2021 22:42:43] "OPTIONS /folios/folios?nome=jna HTTP/1.1" 200 -
127.0.0.1 - - [02/Apr/2021 22:42:43] "OPTIONS /users/foto/jna?seed=1617399762966 HTTP/1.1" 200 -
127.0.0.1 - - [02/Apr/2021 22:42:43] "OPTIONS /users/foto/jna HTTP/1.1" 200 -
127.0.0.1 - - [02/Apr/2021 22:42:43] "GET /users/users?nome=jna HTTP/1.1" 200 -
127.0.0.1 - - [02/Apr/2021 22:42:43] "GET /folios/folios?nome=jna HTTP/1.1" 200 -
127.0.0.1 - - [02/Apr/2021 22:42:43] "GET /users/foto/jna?seed=1617399762966 HTTP/1.1" 200 -
127.0.0.1 - - [02/Apr/2021 22:42:43] "GET /users/foto/jna HTTP/1.1" 304 -
127.0.0.1 - - [02/Apr/2021 22:42:43] "OPTIONS /folios/tags?nome=jna HTTP/1.1" 200 -
127.0.0.1 - - [02/Apr/2021 22:42:43] "OPTIONS /folios/index?nome=jna HTTP/1.1" 200 -
127.0.0.1 - - [02/Apr/2021 22:42:44] "GET /folios/tags?nome=jna HTTP/1.1" 200 -
127.0.0.1 - - [02/Apr/2021 22:42:44] "GET /folios/index?nome=jna HTTP/1.1" 200 -
127.0.0.1 - - [02/Apr/2021 22:43:58] "GET /analise/foliosnames HTTP/1.1" 200 -
127.0.0.1 - - [02/Apr/2021 22:44:09] "OPTIONS /login HTTP/1.1" 200 -
127.0.0.1 - - [02/Apr/2021 22:44:09] "POST /login HTTP/1.1" 200 -
127.0.0.1 - - [02/Apr/2021 22:52:46] "GET /analise/foliosnames HTTP/1.1" 200 -
127.0.0.1 - - [02/Apr/2021 22:53:10] "GET /analise/foliosnames HTTP/1.1" 200 -
127.0.0.1 - - [02/Apr/2021 22:53:14] "GET /analise/pesquisa?pesquisa=Braga&selectedFolio=Todos&tipo=texto&versao=todas&resultado=periodo HTTP/1.1" 200 -
127.0.0.1 - - [02/Apr/2021 23:04:49] "GET /analise/foliosnames HTTP/1.1" 200 -
127.0.0.1 - - [02/Apr/2021 23:04:56] "GET /analise/pesquisa?pesquisa=Braga&selectedFolio=Todos&tipo=texto&versao=todas&resultado=periodo HTTP/1.1" 200 -
127.0.0.1 - - [02/Apr/2021 23:04:59] "GET /analise/folio/TM-F0089 HTTP/1.1" 200 -
127.0.0.1 - - [02/Apr/2021 23:10:04] "OPTIONS /login HTTP/1.1" 200 -
127.0.0.1 - - [02/Apr/2021 23:10:04] "POST /login HTTP/1.1" 200 -
127.0.0.1 - - [02/Apr/2021 23:10:04] "OPTIONS /users/users?nome=jna HTTP/1.1" 200 -
127.0.0.1 - - [02/Apr/2021 23:10:04] "OPTIONS /folios/folios?nome=jna HTTP/1.1" 200 -
127.0.0.1 - - [02/Apr/2021 23:10:04] "OPTIONS /users/foto/jna?seed=1617401404345 HTTP/1.1" 200 -
127.0.0.1 - - [02/Apr/2021 23:10:04] "OPTIONS /users/foto/jna HTTP/1.1" 200 -
127.0.0.1 - - [02/Apr/2021 23:10:04] "GET /users/users?nome=jna HTTP/1.1" 200 -
127.0.0.1 - - [02/Apr/2021 23:10:04] "GET /folios/folios?nome=jna HTTP/1.1" 200 -
127.0.0.1 - - [02/Apr/2021 23:10:04] "GET /users/foto/jna?seed=1617401404345 HTTP/1.1" 200 -
127.0.0.1 - - [02/Apr/2021 23:10:05] "OPTIONS /folios/tags?nome=jna HTTP/1.1" 200 -
127.0.0.1 - - [02/Apr/2021 23:10:05] "OPTIONS /folios/index?nome=jna HTTP/1.1" 200 -
127.0.0.1 - - [02/Apr/2021 23:10:05] "GET /folios/tags?nome=jna HTTP/1.1" 200 -
127.0.0.1 - - [02/Apr/2021 23:10:06] "GET /folios/index?nome=jna HTTP/1.1" 200 -
127.0.0.1 - - [02/Apr/2021 23:30:10] "GET /analise/foliosnames HTTP/1.1" 200 -
127.0.0.1 - - [02/Apr/2021 23:31:02] "OPTIONS /login HTTP/1.1" 200 -
127.0.0.1 - - [02/Apr/2021 23:31:03] "POST /login HTTP/1.1" 200 -
127.0.0.1 - - [02/Apr/2021 23:31:04] "OPTIONS /users/users?nome=jna HTTP/1.1" 200 -
127.0.0.1 - - [02/Apr/2021 23:31:04] "OPTIONS /users/foto/jna?seed=1617402662282 HTTP/1.1" 200 -
127.0.0.1 - - [02/Apr/2021 23:31:04] "GET /users/users?nome=jna HTTP/1.1" 200 -
127.0.0.1 - - [02/Apr/2021 23:31:04] "OPTIONS /folios/folios?nome=jna HTTP/1.1" 200 -
127.0.0.1 - - [02/Apr/2021 23:31:04] "OPTIONS /users/foto/jna HTTP/1.1" 200 -
127.0.0.1 - - [02/Apr/2021 23:31:04] "GET /users/foto/jna?seed=1617402662282 HTTP/1.1" 200 -
127.0.0.1 - - [02/Apr/2021 23:31:04] "GET /folios/folios?nome=jna HTTP/1.1" 200 -
127.0.0.1 - - [02/Apr/2021 23:31:05] "OPTIONS /folios/tags?nome=jna HTTP/1.1" 200 -
127.0.0.1 - - [02/Apr/2021 23:31:05] "OPTIONS /folios/index?nome=jna HTTP/1.1" 200 -
127.0.0.1 - - [02/Apr/2021 23:31:05] "GET /folios/tags?nome=jna HTTP/1.1" 200 -
127.0.0.1 - - [02/Apr/2021 23:31:05] "GET /folios/index?nome=jna HTTP/1.1" 200 -
127.0.0.1 - - [02/Apr/2021 23:31:11] "GET /analise/foliosnames HTTP/1.1" 200 -
127.0.0.1 - - [02/Apr/2021 23:31:22] "GET /analise/foliosnames HTTP/1.1" 200 -
127.0.0.1 - - [02/Apr/2021 23:31:30] "OPTIONS /users/users?nome=jna HTTP/1.1" 200 -
127.0.0.1 - - [02/Apr/2021 23:31:30] "OPTIONS /folios/folios?nome=jna HTTP/1.1" 200 -
127.0.0.1 - - [02/Apr/2021 23:31:30] "OPTIONS /users/foto/jna?seed=1617402688473 HTTP/1.1" 200 -
127.0.0.1 - - [02/Apr/2021 23:31:30] "OPTIONS /users/foto/jna HTTP/1.1" 200 -
127.0.0.1 - - [02/Apr/2021 23:31:30] "GET /users/users?nome=jna HTTP/1.1" 200 -
127.0.0.1 - - [02/Apr/2021 23:31:30] "GET /folios/folios?nome=jna HTTP/1.1" 200 -
127.0.0.1 - - [02/Apr/2021 23:31:30] "GET /users/foto/jna?seed=1617402688473 HTTP/1.1" 200 -
127.0.0.1 - - [02/Apr/2021 23:31:31] "OPTIONS /folios/tags?nome=jna HTTP/1.1" 200 -
127.0.0.1 - - [02/Apr/2021 23:31:31] "OPTIONS /folios/index?nome=jna HTTP/1.1" 200 -
127.0.0.1 - - [02/Apr/2021 23:31:31] "GET /folios/tags?nome=jna HTTP/1.1" 200 -
127.0.0.1 - - [02/Apr/2021 23:31:31] "GET /folios/index?nome=jna HTTP/1.1" 200 -
127.0.0.1 - - [02/Apr/2021 23:31:52] "OPTIONS /login HTTP/1.1" 200 -
127.0.0.1 - - [02/Apr/2021 23:31:53] "POST /login HTTP/1.1" 200 -
127.0.0.1 - - [02/Apr/2021 23:31:58] "OPTIONS /login HTTP/1.1" 200 -
127.0.0.1 - - [02/Apr/2021 23:31:59] "POST /login HTTP/1.1" 200 -
127.0.0.1 - - [02/Apr/2021 23:31:59] "OPTIONS /users/users?nome=jna HTTP/1.1" 200 -
127.0.0.1 - - [02/Apr/2021 23:31:59] "OPTIONS /folios/folios?nome=jna HTTP/1.1" 200 -
127.0.0.1 - - [02/Apr/2021 23:31:59] "OPTIONS /users/foto/jna?seed=1617402719169 HTTP/1.1" 200 -
127.0.0.1 - - [02/Apr/2021 23:31:59] "OPTIONS /users/foto/jna HTTP/1.1" 200 -
127.0.0.1 - - [02/Apr/2021 23:31:59] "GET /users/users?nome=jna HTTP/1.1" 200 -
127.0.0.1 - - [02/Apr/2021 23:31:59] "GET /folios/folios?nome=jna HTTP/1.1" 200 -
127.0.0.1 - - [02/Apr/2021 23:31:59] "GET /users/foto/jna?seed=1617402719169 HTTP/1.1" 200 -
127.0.0.1 - - [02/Apr/2021 23:31:59] "GET /users/foto/jna HTTP/1.1" 304 -
127.0.0.1 - - [02/Apr/2021 23:32:00] "OPTIONS /folios/tags?nome=jna HTTP/1.1" 200 -
127.0.0.1 - - [02/Apr/2021 23:32:00] "OPTIONS /folios/index?nome=jna HTTP/1.1" 200 -
127.0.0.1 - - [02/Apr/2021 23:32:00] "GET /folios/tags?nome=jna HTTP/1.1" 200 -
127.0.0.1 - - [02/Apr/2021 23:32:00] "GET /folios/index?nome=jna HTTP/1.1" 200 -
127.0.0.1 - - [02/Apr/2021 23:41:34] "GET /analise/foliosnames HTTP/1.1" 200 -
127.0.0.1 - - [02/Apr/2021 23:41:46] "OPTIONS /users/users?nome=jna HTTP/1.1" 200 -
127.0.0.1 - - [02/Apr/2021 23:41:46] "OPTIONS /folios/folios?nome=jna HTTP/1.1" 200 -
127.0.0.1 - - [02/Apr/2021 23:41:46] "OPTIONS /users/foto/jna?seed=1617403303759 HTTP/1.1" 200 -
127.0.0.1 - - [02/Apr/2021 23:41:46] "OPTIONS /users/foto/jna HTTP/1.1" 200 -
127.0.0.1 - - [02/Apr/2021 23:41:46] "GET /users/users?nome=jna HTTP/1.1" 200 -
127.0.0.1 - - [02/Apr/2021 23:41:46] "GET /folios/folios?nome=jna HTTP/1.1" 200 -
127.0.0.1 - - [02/Apr/2021 23:41:46] "GET /users/foto/jna?seed=1617403303759 HTTP/1.1" 200 -
127.0.0.1 - - [02/Apr/2021 23:41:46] "GET /users/foto/jna HTTP/1.1" 200 -
127.0.0.1 - - [02/Apr/2021 23:41:47] "OPTIONS /folios/tags?nome=jna HTTP/1.1" 200 -
127.0.0.1 - - [02/Apr/2021 23:41:47] "OPTIONS /folios/index?nome=jna HTTP/1.1" 200 -
127.0.0.1 - - [02/Apr/2021 23:41:47] "GET /folios/tags?nome=jna HTTP/1.1" 200 -
127.0.0.1 - - [02/Apr/2021 23:41:47] "GET /folios/index?nome=jna HTTP/1.1" 200 -
127.0.0.1 - - [03/Apr/2021 00:21:20] "OPTIONS /users/users?nome=undefined HTTP/1.1" 200 -
127.0.0.1 - - [03/Apr/2021 00:21:20] "OPTIONS /folios/folios?nome=undefined HTTP/1.1" 200 -
127.0.0.1 - - [03/Apr/2021 00:21:20] "OPTIONS /users/foto/undefined?seed=1617405680373 HTTP/1.1" 200 -
127.0.0.1 - - [03/Apr/2021 00:21:20] "OPTIONS /users/foto/undefined HTTP/1.1" 200 -
127.0.0.1 - - [03/Apr/2021 00:21:20] "GET /folios/folios?nome=undefined HTTP/1.1" 200 -
127.0.0.1 - - [03/Apr/2021 00:21:20] "GET /users/foto/undefined?seed=1617405680373 HTTP/1.1" 200 -
127.0.0.1 - - [03/Apr/2021 00:21:20] "GET /users/users?nome=undefined HTTP/1.1" 200 -
127.0.0.1 - - [03/Apr/2021 00:21:20] "GET /users/foto/undefined HTTP/1.1" 200 -
127.0.0.1 - - [03/Apr/2021 00:21:21] "OPTIONS /folios/tags?nome=undefined HTTP/1.1" 200 -
127.0.0.1 - - [03/Apr/2021 00:21:21] "OPTIONS /folios/index?nome=undefined HTTP/1.1" 200 -
127.0.0.1 - - [03/Apr/2021 00:21:21] "GET /folios/tags?nome=undefined HTTP/1.1" 200 -
127.0.0.1 - - [03/Apr/2021 00:21:22] "GET /folios/index?nome=undefined HTTP/1.1" 200 -
127.0.0.1 - - [03/Apr/2021 00:43:24] "GET /analise/foliosnames HTTP/1.1" 200 -
127.0.0.1 - - [05/Apr/2021 18:47:24] "GET /analise/foliosnames HTTP/1.1" 200 -
127.0.0.1 - - [05/Apr/2021 18:48:05] "OPTIONS /login HTTP/1.1" 200 -
127.0.0.1 - - [05/Apr/2021 18:48:05] "POST /login HTTP/1.1" 200 -
127.0.0.1 - - [05/Apr/2021 18:48:06] "OPTIONS /users/users?nome=obelo HTTP/1.1" 200 -
127.0.0.1 - - [05/Apr/2021 18:48:06] "OPTIONS /folios/folios?nome=obelo HTTP/1.1" 200 -
127.0.0.1 - - [05/Apr/2021 18:48:06] "OPTIONS /users/foto/obelo?seed=1617644885974 HTTP/1.1" 200 -
127.0.0.1 - - [05/Apr/2021 18:48:06] "OPTIONS /users/foto/obelo HTTP/1.1" 200 -
127.0.0.1 - - [05/Apr/2021 18:48:06] "GET /folios/folios?nome=obelo HTTP/1.1" 200 -
127.0.0.1 - - [05/Apr/2021 18:48:06] "GET /users/users?nome=obelo HTTP/1.1" 200 -
127.0.0.1 - - [05/Apr/2021 18:48:06] "GET /users/foto/obelo HTTP/1.1" 200 -
127.0.0.1 - - [05/Apr/2021 18:48:06] "GET /users/foto/obelo?seed=1617644885974 HTTP/1.1" 200 -
127.0.0.1 - - [05/Apr/2021 18:48:06] "OPTIONS /folios/tags?nome=obelo HTTP/1.1" 200 -
127.0.0.1 - - [05/Apr/2021 18:48:06] "OPTIONS /folios/index?nome=obelo HTTP/1.1" 200 -
127.0.0.1 - - [05/Apr/2021 18:48:06] "GET /folios/tags?nome=obelo HTTP/1.1" 200 -
127.0.0.1 - - [05/Apr/2021 18:48:06] "GET /folios/index?nome=obelo HTTP/1.1" 200 -
127.0.0.1 - - [05/Apr/2021 18:48:30] "OPTIONS /users/foto/obelo?seed=1617644910494 HTTP/1.1" 200 -
127.0.0.1 - - [05/Apr/2021 18:48:30] "OPTIONS /users/foto/obelo HTTP/1.1" 200 -
127.0.0.1 - - [05/Apr/2021 18:48:30] "OPTIONS /folios/folios?nome=obelo HTTP/1.1" 200 -
127.0.0.1 - - [05/Apr/2021 18:48:30] "GET /folios/folios?nome=obelo HTTP/1.1" 200 -
127.0.0.1 - - [05/Apr/2021 18:48:30] "GET /users/foto/obelo?seed=1617644910494 HTTP/1.1" 200 -
 * Serving Flask app "tommi.py"
 * Environment: production
   WARNING: Do not use the development server in a production environment.
   Use a production WSGI server instead.
 * Debug mode: off
 * Running on http://127.0.0.1:5000/ (Press CTRL+C to quit)
127.0.0.1 - - [18/Apr/2021 23:37:00] "OPTIONS /elementos/elementos?nome=jna HTTP/1.1" 200 -
127.0.0.1 - - [18/Apr/2021 23:37:00] "OPTIONS /users/foto/jna?seed=1618785420269 HTTP/1.1" 200 -
127.0.0.1 - - [18/Apr/2021 23:37:00] "OPTIONS /users/foto/jna HTTP/1.1" 200 -
127.0.0.1 - - [18/Apr/2021 23:37:00] "GET /users/foto/jna?seed=1618785420269 HTTP/1.1" 200 -
127.0.0.1 - - [18/Apr/2021 23:37:00] "GET /elementos/elementos?nome=jna HTTP/1.1" 200 -
127.0.0.1 - - [18/Apr/2021 23:48:31] "POST /users/pedidos/registar HTTP/1.1" 200 -
127.0.0.1 - - [18/Apr/2021 23:48:37] "OPTIONS /login HTTP/1.1" 200 -
127.0.0.1 - - [18/Apr/2021 23:48:37] "POST /login HTTP/1.1" 200 -
127.0.0.1 - - [18/Apr/2021 23:48:37] "OPTIONS /users/users?nome=cat HTTP/1.1" 200 -
127.0.0.1 - - [18/Apr/2021 23:48:37] "OPTIONS /folios/folios?nome=cat HTTP/1.1" 404 -
127.0.0.1 - - [18/Apr/2021 23:48:37] "OPTIONS /users/foto/cat?seed=1618786117584 HTTP/1.1" 200 -
127.0.0.1 - - [18/Apr/2021 23:48:37] "OPTIONS /users/foto/cat HTTP/1.1" 200 -
127.0.0.1 - - [18/Apr/2021 23:48:37] "GET /users/users?nome=cat HTTP/1.1" 200 -
127.0.0.1 - - [18/Apr/2021 23:48:38] "GET /users/foto/cat?seed=1618786117584 HTTP/1.1" 200 -
127.0.0.1 - - [18/Apr/2021 23:48:38] "GET /users/foto/cat HTTP/1.1" 200 -
127.0.0.1 - - [18/Apr/2021 23:49:06] "OPTIONS /elementos/elementos?nome=cat HTTP/1.1" 200 -
127.0.0.1 - - [18/Apr/2021 23:49:06] "OPTIONS /users/foto/cat?seed=1618786146480 HTTP/1.1" 200 -
127.0.0.1 - - [18/Apr/2021 23:49:06] "OPTIONS /users/foto/cat HTTP/1.1" 200 -
127.0.0.1 - - [18/Apr/2021 23:49:07] "GET /users/foto/cat?seed=1618786146480 HTTP/1.1" 200 -
127.0.0.1 - - [18/Apr/2021 23:49:07] "GET /elementos/elementos?nome=cat HTTP/1.1" 200 -
127.0.0.1 - - [18/Apr/2021 23:56:12] "POST /login HTTP/1.1" 200 -
127.0.0.1 - - [18/Apr/2021 23:56:13] "POST /login HTTP/1.1" 200 -
127.0.0.1 - - [18/Apr/2021 23:56:20] "POST /login HTTP/1.1" 200 -
127.0.0.1 - - [18/Apr/2021 23:56:35] "GET /analise/foliosnames HTTP/1.1" 200 -
127.0.0.1 - - [18/Apr/2021 23:56:43] "OPTIONS /login HTTP/1.1" 200 -
127.0.0.1 - - [18/Apr/2021 23:56:43] "POST /login HTTP/1.1" 200 -
127.0.0.1 - - [18/Apr/2021 23:56:43] "OPTIONS /users/users?nome=jna HTTP/1.1" 200 -
127.0.0.1 - - [18/Apr/2021 23:56:43] "OPTIONS /folios/folios?nome=jna HTTP/1.1" 404 -
127.0.0.1 - - [18/Apr/2021 23:56:43] "OPTIONS /users/foto/jna?seed=1618786603508 HTTP/1.1" 200 -
127.0.0.1 - - [18/Apr/2021 23:56:43] "OPTIONS /users/foto/jna HTTP/1.1" 200 -
127.0.0.1 - - [18/Apr/2021 23:56:43] "GET /users/users?nome=jna HTTP/1.1" 200 -
127.0.0.1 - - [18/Apr/2021 23:56:43] "GET /users/foto/jna?seed=1618786603508 HTTP/1.1" 200 -
127.0.0.1 - - [19/Apr/2021 00:05:36] "OPTIONS /login HTTP/1.1" 200 -
127.0.0.1 - - [19/Apr/2021 00:05:36] "POST /login HTTP/1.1" 200 -
127.0.0.1 - - [19/Apr/2021 00:05:36] "OPTIONS /users/users?nome=cat HTTP/1.1" 200 -
127.0.0.1 - - [19/Apr/2021 00:05:36] "OPTIONS /folios/folios?nome=cat HTTP/1.1" 404 -
127.0.0.1 - - [19/Apr/2021 00:05:36] "OPTIONS /users/foto/cat?seed=1618787136474 HTTP/1.1" 200 -
127.0.0.1 - - [19/Apr/2021 00:05:36] "OPTIONS /users/foto/cat HTTP/1.1" 200 -
127.0.0.1 - - [19/Apr/2021 00:05:36] "GET /users/users?nome=cat HTTP/1.1" 200 -
127.0.0.1 - - [19/Apr/2021 00:05:36] "GET /users/foto/cat?seed=1618787136474 HTTP/1.1" 200 -
127.0.0.1 - - [19/Apr/2021 00:08:19] "OPTIONS /login HTTP/1.1" 200 -
127.0.0.1 - - [19/Apr/2021 00:08:19] "POST /login HTTP/1.1" 200 -
127.0.0.1 - - [19/Apr/2021 00:08:19] "OPTIONS /users/users?nome=cat HTTP/1.1" 200 -
127.0.0.1 - - [19/Apr/2021 00:08:19] "OPTIONS /folios/folios?nome=cat HTTP/1.1" 404 -
127.0.0.1 - - [19/Apr/2021 00:08:19] "OPTIONS /users/foto/cat?seed=1618787299196 HTTP/1.1" 200 -
127.0.0.1 - - [19/Apr/2021 00:08:19] "OPTIONS /users/foto/cat HTTP/1.1" 200 -
127.0.0.1 - - [19/Apr/2021 00:08:19] "GET /users/users?nome=cat HTTP/1.1" 200 -
127.0.0.1 - - [19/Apr/2021 00:08:19] "GET /users/foto/cat?seed=1618787299196 HTTP/1.1" 200 -
127.0.0.1 - - [19/Apr/2021 00:31:13] "OPTIONS /login HTTP/1.1" 200 -
127.0.0.1 - - [19/Apr/2021 00:31:14] "POST /login HTTP/1.1" 200 -
127.0.0.1 - - [19/Apr/2021 00:31:14] "OPTIONS /users/users?nome=cat HTTP/1.1" 200 -
127.0.0.1 - - [19/Apr/2021 00:31:14] "OPTIONS /folios/folios?nome=cat HTTP/1.1" 404 -
127.0.0.1 - - [19/Apr/2021 00:31:14] "OPTIONS /users/foto/cat?seed=1618788674161 HTTP/1.1" 200 -
127.0.0.1 - - [19/Apr/2021 00:31:14] "OPTIONS /users/foto/cat HTTP/1.1" 200 -
127.0.0.1 - - [19/Apr/2021 00:31:14] "GET /users/users?nome=cat HTTP/1.1" 200 -
127.0.0.1 - - [19/Apr/2021 00:31:14] "GET /users/foto/cat?seed=1618788674161 HTTP/1.1" 200 -
127.0.0.1 - - [19/Apr/2021 00:31:18] "OPTIONS /elementos/elementos?nome=cat HTTP/1.1" 200 -
127.0.0.1 - - [19/Apr/2021 00:31:18] "OPTIONS /users/foto/cat?seed=1618788677852 HTTP/1.1" 200 -
127.0.0.1 - - [19/Apr/2021 00:31:18] "GET /users/foto/cat?seed=1618788677852 HTTP/1.1" 200 -
127.0.0.1 - - [19/Apr/2021 00:31:18] "GET /elementos/elementos?nome=cat HTTP/1.1" 200 -
127.0.0.1 - - [19/Apr/2021 00:31:21] "OPTIONS /users/foto/cat?seed=1618788681553 HTTP/1.1" 200 -
127.0.0.1 - - [19/Apr/2021 00:31:21] "OPTIONS /users/foto/cat HTTP/1.1" 200 -
127.0.0.1 - - [19/Apr/2021 00:31:21] "GET /users/foto/cat?seed=1618788681553 HTTP/1.1" 200 -
127.0.0.1 - - [19/Apr/2021 00:32:27] "OPTIONS /import/passo6/?nome=cat HTTP/1.1" 200 -
127.0.0.1 - - [19/Apr/2021 00:32:45] "OPTIONS /import/passo6/?nome=cat HTTP/1.1" 200 -
127.0.0.1 - - [19/Apr/2021 00:32:46] "POST /import/passo6/?nome=cat HTTP/1.1" 200 -
127.0.0.1 - - [19/Apr/2021 00:32:47] "OPTIONS /elementos/elementos?nome=cat HTTP/1.1" 200 -
127.0.0.1 - - [19/Apr/2021 00:32:47] "OPTIONS /users/foto/cat?seed=1618788766773 HTTP/1.1" 200 -
127.0.0.1 - - [19/Apr/2021 00:32:47] "OPTIONS /users/foto/cat HTTP/1.1" 200 -
127.0.0.1 - - [19/Apr/2021 00:32:47] "GET /users/foto/cat?seed=1618788766773 HTTP/1.1" 200 -
127.0.0.1 - - [19/Apr/2021 00:32:47] "GET /elementos/elementos?nome=cat HTTP/1.1" 200 -
127.0.0.1 - - [19/Apr/2021 00:41:49] "GET /analise/pesquisa?pesquisa=asd&selectedFolio=Todos&tipo=texto&versao=todas&resultado=periodo HTTP/1.1" 200 -
127.0.0.1 - - [19/Apr/2021 16:37:45] "GET /analise/foliosnames HTTP/1.1" 200 -
[2021-04-19 16:37:54,077] ERROR in app: Exception on /login [POST]
Traceback (most recent call last):
  File "/usr/local/lib/python3.6/dist-packages/py2neo/client/__init__.py", line 742, in acquire
    cx = self._free_list.popleft()
IndexError: pop from an empty deque

During handling of the above exception, another exception occurred:

Traceback (most recent call last):
  File "/usr/local/lib/python3.6/dist-packages/flask/app.py", line 2292, in wsgi_app
    response = self.full_dispatch_request()
  File "/usr/local/lib/python3.6/dist-packages/flask/app.py", line 1815, in full_dispatch_request
    rv = self.handle_user_exception(e)
  File "/usr/local/lib/python3.6/dist-packages/flask/app.py", line 1718, in handle_user_exception
    reraise(exc_type, exc_value, tb)
  File "/usr/local/lib/python3.6/dist-packages/flask/_compat.py", line 35, in reraise
    raise value
  File "/usr/local/lib/python3.6/dist-packages/flask/app.py", line 1813, in full_dispatch_request
    rv = self.dispatch_request()
  File "/usr/local/lib/python3.6/dist-packages/flask/app.py", line 1799, in dispatch_request
    return self.view_functions[rule.endpoint](**req.view_args)
  File "/home/cartos.di.uminho.pt/LEI/cartos-master/app/base/routes.py", line 223, in login
    user = g.evaluate('match (x:User) where x._id=$v return x',v=_id)
  File "/usr/local/lib/python3.6/dist-packages/py2neo/database/__init__.py", line 498, in evaluate
    return self.auto().evaluate(cypher, parameters, **kwparameters)
  File "/usr/local/lib/python3.6/dist-packages/py2neo/database/work.py", line 170, in evaluate
    return self.run(cypher, parameters, **kwparameters).evaluate(0)
  File "/usr/local/lib/python3.6/dist-packages/py2neo/database/work.py", line 127, in run
    readonly=self.readonly)
  File "/usr/local/lib/python3.6/dist-packages/py2neo/client/__init__.py", line 1248, in auto_run
    cx = self.acquire(graph_name, readonly)
  File "/usr/local/lib/python3.6/dist-packages/py2neo/client/__init__.py", line 1075, in acquire
    cx = pool.acquire(force_reset=force_reset)
  File "/usr/local/lib/python3.6/dist-packages/py2neo/client/__init__.py", line 749, in acquire
    cx = self.connect()
  File "/usr/local/lib/python3.6/dist-packages/py2neo/client/__init__.py", line 702, in connect
    self._bytes_sent += cx.bytes_sent
  File "/usr/local/lib/python3.6/dist-packages/py2neo/client/__init__.py", line 184, in bytes_sent
    raise NotImplementedError
NotImplementedError
127.0.0.1 - - [19/Apr/2021 16:37:54] "POST /login HTTP/1.1" 500 -
Error on request:
Traceback (most recent call last):
  File "/usr/local/lib/python3.6/dist-packages/py2neo/client/__init__.py", line 742, in acquire
    cx = self._free_list.popleft()
IndexError: pop from an empty deque

During handling of the above exception, another exception occurred:

Traceback (most recent call last):
  File "/usr/local/lib/python3.6/dist-packages/flask/app.py", line 2292, in wsgi_app
    response = self.full_dispatch_request()
  File "/usr/local/lib/python3.6/dist-packages/flask/app.py", line 1815, in full_dispatch_request
    rv = self.handle_user_exception(e)
  File "/usr/local/lib/python3.6/dist-packages/flask/app.py", line 1718, in handle_user_exception
    reraise(exc_type, exc_value, tb)
  File "/usr/local/lib/python3.6/dist-packages/flask/_compat.py", line 35, in reraise
    raise value
  File "/usr/local/lib/python3.6/dist-packages/flask/app.py", line 1813, in full_dispatch_request
    rv = self.dispatch_request()
  File "/usr/local/lib/python3.6/dist-packages/flask/app.py", line 1799, in dispatch_request
    return self.view_functions[rule.endpoint](**req.view_args)
  File "/home/cartos.di.uminho.pt/LEI/cartos-master/app/base/routes.py", line 223, in login
    user = g.evaluate('match (x:User) where x._id=$v return x',v=_id)
  File "/usr/local/lib/python3.6/dist-packages/py2neo/database/__init__.py", line 498, in evaluate
    return self.auto().evaluate(cypher, parameters, **kwparameters)
  File "/usr/local/lib/python3.6/dist-packages/py2neo/database/work.py", line 170, in evaluate
    return self.run(cypher, parameters, **kwparameters).evaluate(0)
  File "/usr/local/lib/python3.6/dist-packages/py2neo/database/work.py", line 127, in run
    readonly=self.readonly)
  File "/usr/local/lib/python3.6/dist-packages/py2neo/client/__init__.py", line 1248, in auto_run
    cx = self.acquire(graph_name, readonly)
  File "/usr/local/lib/python3.6/dist-packages/py2neo/client/__init__.py", line 1075, in acquire
    cx = pool.acquire(force_reset=force_reset)
  File "/usr/local/lib/python3.6/dist-packages/py2neo/client/__init__.py", line 749, in acquire
    cx = self.connect()
  File "/usr/local/lib/python3.6/dist-packages/py2neo/client/__init__.py", line 702, in connect
    self._bytes_sent += cx.bytes_sent
  File "/usr/local/lib/python3.6/dist-packages/py2neo/client/__init__.py", line 184, in bytes_sent
    raise NotImplementedError
NotImplementedError

During handling of the above exception, another exception occurred:

Traceback (most recent call last):
  File "/usr/local/lib/python3.6/dist-packages/werkzeug/serving.py", line 302, in run_wsgi
    execute(self.server.app)
  File "/usr/local/lib/python3.6/dist-packages/werkzeug/serving.py", line 290, in execute
    application_iter = app(environ, start_response)
  File "/usr/local/lib/python3.6/dist-packages/flask/app.py", line 2309, in __call__
    return self.wsgi_app(environ, start_response)
  File "/usr/local/lib/python3.6/dist-packages/flask/app.py", line 2295, in wsgi_app
    response = self.handle_exception(e)
  File "/usr/local/lib/python3.6/dist-packages/flask/app.py", line 1748, in handle_exception
    return self.finalize_request(handler(e), from_error_handler=True)
  File "/home/cartos.di.uminho.pt/LEI/cartos-master/app/base/routes.py", line 274, in internal_error
    return render_template('errors/page_500.html'), 500
  File "/usr/local/lib/python3.6/dist-packages/flask/templating.py", line 133, in render_template
    ctx.app.update_template_context(context)
  File "/usr/local/lib/python3.6/dist-packages/flask/app.py", line 792, in update_template_context
    context.update(func())
  File "/usr/local/lib/python3.6/dist-packages/flask_login/utils.py", line 379, in _user_context_processor
    return dict(current_user=_get_user())
  File "/usr/local/lib/python3.6/dist-packages/flask_login/utils.py", line 346, in _get_user
    current_app.login_manager._load_user()
  File "/usr/local/lib/python3.6/dist-packages/flask_login/login_manager.py", line 303, in _load_user
    "Missing user_loader or request_loader. Refer to "
Exception: Missing user_loader or request_loader. Refer to http://flask-login.readthedocs.io/#how-it-works for more info.
127.0.0.1 - - [19/Apr/2021 16:37:55] "POST /login HTTP/1.1" 200 -
127.0.0.1 - - [19/Apr/2021 16:38:05] "POST /login HTTP/1.1" 200 -
127.0.0.1 - - [19/Apr/2021 16:38:16] "POST /login HTTP/1.1" 200 -
127.0.0.1 - - [19/Apr/2021 16:38:22] "POST /login HTTP/1.1" 200 -
127.0.0.1 - - [19/Apr/2021 16:52:48] "GET /analise/foliosnames HTTP/1.1" 200 -
127.0.0.1 - - [19/Apr/2021 16:52:56] "GET /analise/pesquisa?pesquisa=braga&selectedFolio=Todos&tipo=texto&versao=todas&resultado=periodo HTTP/1.1" 200 -
127.0.0.1 - - [19/Apr/2021 16:53:00] "GET /analise/foliosnames HTTP/1.1" 200 -
127.0.0.1 - - [19/Apr/2021 16:53:11] "GET /analise/pesquisa?pesquisa=braga&selectedFolio=Todos&tipo=texto&versao=todas&resultado=periodo HTTP/1.1" 200 -
127.0.0.1 - - [20/Apr/2021 15:18:18] "GET /analise/foliosnames HTTP/1.1" 200 -
[2021-04-20 15:18:35,470] ERROR in app: Exception on /login [POST]
Traceback (most recent call last):
  File "/usr/local/lib/python3.6/dist-packages/py2neo/client/__init__.py", line 742, in acquire
    cx = self._free_list.popleft()
IndexError: pop from an empty deque

During handling of the above exception, another exception occurred:

Traceback (most recent call last):
  File "/usr/local/lib/python3.6/dist-packages/flask/app.py", line 2292, in wsgi_app
    response = self.full_dispatch_request()
  File "/usr/local/lib/python3.6/dist-packages/flask/app.py", line 1815, in full_dispatch_request
    rv = self.handle_user_exception(e)
  File "/usr/local/lib/python3.6/dist-packages/flask/app.py", line 1718, in handle_user_exception
    reraise(exc_type, exc_value, tb)
  File "/usr/local/lib/python3.6/dist-packages/flask/_compat.py", line 35, in reraise
    raise value
  File "/usr/local/lib/python3.6/dist-packages/flask/app.py", line 1813, in full_dispatch_request
    rv = self.dispatch_request()
  File "/usr/local/lib/python3.6/dist-packages/flask/app.py", line 1799, in dispatch_request
    return self.view_functions[rule.endpoint](**req.view_args)
  File "/home/cartos.di.uminho.pt/LEI/cartos-master/app/base/routes.py", line 223, in login
    user = g.evaluate('match (x:User) where x._id=$v return x',v=_id)
  File "/usr/local/lib/python3.6/dist-packages/py2neo/database/__init__.py", line 498, in evaluate
    return self.auto().evaluate(cypher, parameters, **kwparameters)
  File "/usr/local/lib/python3.6/dist-packages/py2neo/database/work.py", line 170, in evaluate
    return self.run(cypher, parameters, **kwparameters).evaluate(0)
  File "/usr/local/lib/python3.6/dist-packages/py2neo/database/work.py", line 127, in run
    readonly=self.readonly)
  File "/usr/local/lib/python3.6/dist-packages/py2neo/client/__init__.py", line 1248, in auto_run
    cx = self.acquire(graph_name, readonly)
  File "/usr/local/lib/python3.6/dist-packages/py2neo/client/__init__.py", line 1075, in acquire
    cx = pool.acquire(force_reset=force_reset)
  File "/usr/local/lib/python3.6/dist-packages/py2neo/client/__init__.py", line 749, in acquire
    cx = self.connect()
  File "/usr/local/lib/python3.6/dist-packages/py2neo/client/__init__.py", line 702, in connect
    self._bytes_sent += cx.bytes_sent
  File "/usr/local/lib/python3.6/dist-packages/py2neo/client/__init__.py", line 184, in bytes_sent
    raise NotImplementedError
NotImplementedError
127.0.0.1 - - [20/Apr/2021 15:18:35] "POST /login HTTP/1.1" 500 -
Error on request:
Traceback (most recent call last):
  File "/usr/local/lib/python3.6/dist-packages/py2neo/client/__init__.py", line 742, in acquire
    cx = self._free_list.popleft()
IndexError: pop from an empty deque

During handling of the above exception, another exception occurred:

Traceback (most recent call last):
  File "/usr/local/lib/python3.6/dist-packages/flask/app.py", line 2292, in wsgi_app
    response = self.full_dispatch_request()
  File "/usr/local/lib/python3.6/dist-packages/flask/app.py", line 1815, in full_dispatch_request
    rv = self.handle_user_exception(e)
  File "/usr/local/lib/python3.6/dist-packages/flask/app.py", line 1718, in handle_user_exception
    reraise(exc_type, exc_value, tb)
  File "/usr/local/lib/python3.6/dist-packages/flask/_compat.py", line 35, in reraise
    raise value
  File "/usr/local/lib/python3.6/dist-packages/flask/app.py", line 1813, in full_dispatch_request
    rv = self.dispatch_request()
  File "/usr/local/lib/python3.6/dist-packages/flask/app.py", line 1799, in dispatch_request
    return self.view_functions[rule.endpoint](**req.view_args)
  File "/home/cartos.di.uminho.pt/LEI/cartos-master/app/base/routes.py", line 223, in login
    user = g.evaluate('match (x:User) where x._id=$v return x',v=_id)
  File "/usr/local/lib/python3.6/dist-packages/py2neo/database/__init__.py", line 498, in evaluate
    return self.auto().evaluate(cypher, parameters, **kwparameters)
  File "/usr/local/lib/python3.6/dist-packages/py2neo/database/work.py", line 170, in evaluate
    return self.run(cypher, parameters, **kwparameters).evaluate(0)
  File "/usr/local/lib/python3.6/dist-packages/py2neo/database/work.py", line 127, in run
    readonly=self.readonly)
  File "/usr/local/lib/python3.6/dist-packages/py2neo/client/__init__.py", line 1248, in auto_run
    cx = self.acquire(graph_name, readonly)
  File "/usr/local/lib/python3.6/dist-packages/py2neo/client/__init__.py", line 1075, in acquire
    cx = pool.acquire(force_reset=force_reset)
  File "/usr/local/lib/python3.6/dist-packages/py2neo/client/__init__.py", line 749, in acquire
    cx = self.connect()
  File "/usr/local/lib/python3.6/dist-packages/py2neo/client/__init__.py", line 702, in connect
    self._bytes_sent += cx.bytes_sent
  File "/usr/local/lib/python3.6/dist-packages/py2neo/client/__init__.py", line 184, in bytes_sent
    raise NotImplementedError
NotImplementedError

During handling of the above exception, another exception occurred:

Traceback (most recent call last):
  File "/usr/local/lib/python3.6/dist-packages/werkzeug/serving.py", line 302, in run_wsgi
    execute(self.server.app)
  File "/usr/local/lib/python3.6/dist-packages/werkzeug/serving.py", line 290, in execute
    application_iter = app(environ, start_response)
  File "/usr/local/lib/python3.6/dist-packages/flask/app.py", line 2309, in __call__
    return self.wsgi_app(environ, start_response)
  File "/usr/local/lib/python3.6/dist-packages/flask/app.py", line 2295, in wsgi_app
    response = self.handle_exception(e)
  File "/usr/local/lib/python3.6/dist-packages/flask/app.py", line 1748, in handle_exception
    return self.finalize_request(handler(e), from_error_handler=True)
  File "/home/cartos.di.uminho.pt/LEI/cartos-master/app/base/routes.py", line 274, in internal_error
    return render_template('errors/page_500.html'), 500
  File "/usr/local/lib/python3.6/dist-packages/flask/templating.py", line 133, in render_template
    ctx.app.update_template_context(context)
  File "/usr/local/lib/python3.6/dist-packages/flask/app.py", line 792, in update_template_context
    context.update(func())
  File "/usr/local/lib/python3.6/dist-packages/flask_login/utils.py", line 379, in _user_context_processor
    return dict(current_user=_get_user())
  File "/usr/local/lib/python3.6/dist-packages/flask_login/utils.py", line 346, in _get_user
    current_app.login_manager._load_user()
  File "/usr/local/lib/python3.6/dist-packages/flask_login/login_manager.py", line 303, in _load_user
    "Missing user_loader or request_loader. Refer to "
Exception: Missing user_loader or request_loader. Refer to http://flask-login.readthedocs.io/#how-it-works for more info.
127.0.0.1 - - [20/Apr/2021 15:18:37] "POST /login HTTP/1.1" 200 -
127.0.0.1 - - [20/Apr/2021 15:18:44] "POST /login HTTP/1.1" 200 -
127.0.0.1 - - [20/Apr/2021 15:18:53] "POST /login HTTP/1.1" 200 -
127.0.0.1 - - [20/Apr/2021 15:19:27] "POST /login HTTP/1.1" 200 -
127.0.0.1 - - [20/Apr/2021 15:23:48] "POST /login HTTP/1.1" 200 -
127.0.0.1 - - [20/Apr/2021 15:23:56] "POST /login HTTP/1.1" 200 -
127.0.0.1 - - [20/Apr/2021 15:24:21] "POST /login HTTP/1.1" 200 -
127.0.0.1 - - [20/Apr/2021 16:15:00] "GET /analise/foliosnames HTTP/1.1" 200 -
127.0.0.1 - - [20/Apr/2021 16:16:32] "GET /analise/foliosnames HTTP/1.1" 200 -
127.0.0.1 - - [20/Apr/2021 16:17:15] "GET /analise/foliosnames HTTP/1.1" 200 -
127.0.0.1 - - [20/Apr/2021 16:17:53] "OPTIONS /login HTTP/1.1" 200 -
127.0.0.1 - - [20/Apr/2021 16:17:54] "POST /login HTTP/1.1" 200 -
127.0.0.1 - - [20/Apr/2021 16:18:00] "OPTIONS /login HTTP/1.1" 200 -
127.0.0.1 - - [20/Apr/2021 16:18:00] "POST /login HTTP/1.1" 200 -
127.0.0.1 - - [20/Apr/2021 16:18:05] "OPTIONS /login HTTP/1.1" 200 -
127.0.0.1 - - [20/Apr/2021 16:18:05] "POST /login HTTP/1.1" 200 -
127.0.0.1 - - [20/Apr/2021 16:18:11] "POST /login HTTP/1.1" 200 -
[2021-04-20 16:19:08,900] ERROR in app: Exception on /login [POST]
Traceback (most recent call last):
  File "/usr/local/lib/python3.6/dist-packages/py2neo/client/__init__.py", line 742, in acquire
    cx = self._free_list.popleft()
IndexError: pop from an empty deque

During handling of the above exception, another exception occurred:

Traceback (most recent call last):
  File "/usr/local/lib/python3.6/dist-packages/flask/app.py", line 2292, in wsgi_app
    response = self.full_dispatch_request()
  File "/usr/local/lib/python3.6/dist-packages/flask/app.py", line 1815, in full_dispatch_request
    rv = self.handle_user_exception(e)
  File "/usr/local/lib/python3.6/dist-packages/flask/app.py", line 1718, in handle_user_exception
    reraise(exc_type, exc_value, tb)
  File "/usr/local/lib/python3.6/dist-packages/flask/_compat.py", line 35, in reraise
    raise value
  File "/usr/local/lib/python3.6/dist-packages/flask/app.py", line 1813, in full_dispatch_request
    rv = self.dispatch_request()
  File "/usr/local/lib/python3.6/dist-packages/flask/app.py", line 1799, in dispatch_request
    return self.view_functions[rule.endpoint](**req.view_args)
  File "/home/cartos.di.uminho.pt/LEI/cartos-master/app/base/routes.py", line 223, in login
    user = g.evaluate('match (x:User) where x._id=$v return x',v=_id)
  File "/usr/local/lib/python3.6/dist-packages/py2neo/database/__init__.py", line 498, in evaluate
    return self.auto().evaluate(cypher, parameters, **kwparameters)
  File "/usr/local/lib/python3.6/dist-packages/py2neo/database/work.py", line 170, in evaluate
    return self.run(cypher, parameters, **kwparameters).evaluate(0)
  File "/usr/local/lib/python3.6/dist-packages/py2neo/database/work.py", line 127, in run
    readonly=self.readonly)
  File "/usr/local/lib/python3.6/dist-packages/py2neo/client/__init__.py", line 1248, in auto_run
    cx = self.acquire(graph_name, readonly)
  File "/usr/local/lib/python3.6/dist-packages/py2neo/client/__init__.py", line 1075, in acquire
    cx = pool.acquire(force_reset=force_reset)
  File "/usr/local/lib/python3.6/dist-packages/py2neo/client/__init__.py", line 749, in acquire
    cx = self.connect()
  File "/usr/local/lib/python3.6/dist-packages/py2neo/client/__init__.py", line 702, in connect
    self._bytes_sent += cx.bytes_sent
  File "/usr/local/lib/python3.6/dist-packages/py2neo/client/__init__.py", line 184, in bytes_sent
    raise NotImplementedError
NotImplementedError
127.0.0.1 - - [20/Apr/2021 16:19:08] "POST /login HTTP/1.1" 500 -
Error on request:
Traceback (most recent call last):
  File "/usr/local/lib/python3.6/dist-packages/py2neo/client/__init__.py", line 742, in acquire
    cx = self._free_list.popleft()
IndexError: pop from an empty deque

During handling of the above exception, another exception occurred:

Traceback (most recent call last):
  File "/usr/local/lib/python3.6/dist-packages/flask/app.py", line 2292, in wsgi_app
    response = self.full_dispatch_request()
  File "/usr/local/lib/python3.6/dist-packages/flask/app.py", line 1815, in full_dispatch_request
    rv = self.handle_user_exception(e)
  File "/usr/local/lib/python3.6/dist-packages/flask/app.py", line 1718, in handle_user_exception
    reraise(exc_type, exc_value, tb)
  File "/usr/local/lib/python3.6/dist-packages/flask/_compat.py", line 35, in reraise
    raise value
  File "/usr/local/lib/python3.6/dist-packages/flask/app.py", line 1813, in full_dispatch_request
    rv = self.dispatch_request()
  File "/usr/local/lib/python3.6/dist-packages/flask/app.py", line 1799, in dispatch_request
    return self.view_functions[rule.endpoint](**req.view_args)
  File "/home/cartos.di.uminho.pt/LEI/cartos-master/app/base/routes.py", line 223, in login
    user = g.evaluate('match (x:User) where x._id=$v return x',v=_id)
  File "/usr/local/lib/python3.6/dist-packages/py2neo/database/__init__.py", line 498, in evaluate
    return self.auto().evaluate(cypher, parameters, **kwparameters)
  File "/usr/local/lib/python3.6/dist-packages/py2neo/database/work.py", line 170, in evaluate
    return self.run(cypher, parameters, **kwparameters).evaluate(0)
  File "/usr/local/lib/python3.6/dist-packages/py2neo/database/work.py", line 127, in run
    readonly=self.readonly)
  File "/usr/local/lib/python3.6/dist-packages/py2neo/client/__init__.py", line 1248, in auto_run
    cx = self.acquire(graph_name, readonly)
  File "/usr/local/lib/python3.6/dist-packages/py2neo/client/__init__.py", line 1075, in acquire
    cx = pool.acquire(force_reset=force_reset)
  File "/usr/local/lib/python3.6/dist-packages/py2neo/client/__init__.py", line 749, in acquire
    cx = self.connect()
  File "/usr/local/lib/python3.6/dist-packages/py2neo/client/__init__.py", line 702, in connect
    self._bytes_sent += cx.bytes_sent
  File "/usr/local/lib/python3.6/dist-packages/py2neo/client/__init__.py", line 184, in bytes_sent
    raise NotImplementedError
NotImplementedError

During handling of the above exception, another exception occurred:

Traceback (most recent call last):
  File "/usr/local/lib/python3.6/dist-packages/werkzeug/serving.py", line 302, in run_wsgi
    execute(self.server.app)
  File "/usr/local/lib/python3.6/dist-packages/werkzeug/serving.py", line 290, in execute
    application_iter = app(environ, start_response)
  File "/usr/local/lib/python3.6/dist-packages/flask/app.py", line 2309, in __call__
    return self.wsgi_app(environ, start_response)
  File "/usr/local/lib/python3.6/dist-packages/flask/app.py", line 2295, in wsgi_app
    response = self.handle_exception(e)
  File "/usr/local/lib/python3.6/dist-packages/flask/app.py", line 1748, in handle_exception
    return self.finalize_request(handler(e), from_error_handler=True)
  File "/home/cartos.di.uminho.pt/LEI/cartos-master/app/base/routes.py", line 274, in internal_error
    return render_template('errors/page_500.html'), 500
  File "/usr/local/lib/python3.6/dist-packages/flask/templating.py", line 133, in render_template
    ctx.app.update_template_context(context)
  File "/usr/local/lib/python3.6/dist-packages/flask/app.py", line 792, in update_template_context
    context.update(func())
  File "/usr/local/lib/python3.6/dist-packages/flask_login/utils.py", line 379, in _user_context_processor
    return dict(current_user=_get_user())
  File "/usr/local/lib/python3.6/dist-packages/flask_login/utils.py", line 346, in _get_user
    current_app.login_manager._load_user()
  File "/usr/local/lib/python3.6/dist-packages/flask_login/login_manager.py", line 303, in _load_user
    "Missing user_loader or request_loader. Refer to "
Exception: Missing user_loader or request_loader. Refer to http://flask-login.readthedocs.io/#how-it-works for more info.
127.0.0.1 - - [20/Apr/2021 16:19:10] "POST /login HTTP/1.1" 200 -
127.0.0.1 - - [20/Apr/2021 16:19:36] "POST /login HTTP/1.1" 200 -
127.0.0.1 - - [20/Apr/2021 16:19:58] "OPTIONS /login HTTP/1.1" 200 -
127.0.0.1 - - [20/Apr/2021 16:19:58] "POST /login HTTP/1.1" 200 -
127.0.0.1 - - [20/Apr/2021 16:21:45] "POST /login HTTP/1.1" 200 -
127.0.0.1 - - [20/Apr/2021 16:21:58] "GET /analise/foliosnames HTTP/1.1" 200 -
127.0.0.1 - - [20/Apr/2021 16:22:17] "POST /login HTTP/1.1" 200 -
127.0.0.1 - - [20/Apr/2021 16:27:29] "POST /login HTTP/1.1" 200 -
127.0.0.1 - - [20/Apr/2021 16:27:37] "OPTIONS /login HTTP/1.1" 200 -
127.0.0.1 - - [20/Apr/2021 16:27:37] "POST /login HTTP/1.1" 200 -
127.0.0.1 - - [20/Apr/2021 16:32:41] "POST /login HTTP/1.1" 200 -
127.0.0.1 - - [20/Apr/2021 16:34:43] "GET /analise/foliosnames HTTP/1.1" 200 -
127.0.0.1 - - [20/Apr/2021 16:34:52] "POST /login HTTP/1.1" 200 -
127.0.0.1 - - [20/Apr/2021 16:36:59] "GET /analise/foliosnames HTTP/1.1" 200 -
127.0.0.1 - - [20/Apr/2021 16:45:58] "GET /analise/foliosnames HTTP/1.1" 200 -
127.0.0.1 - - [20/Apr/2021 17:20:52] "GET /home/index HTTP/1.1" 401 -
127.0.0.1 - - [21/Apr/2021 11:44:51] "GET /analise/foliosnames HTTP/1.1" 200 -
[2021-04-21 11:45:01,855] ERROR in app: Exception on /login [POST]
Traceback (most recent call last):
  File "/usr/local/lib/python3.6/dist-packages/py2neo/client/__init__.py", line 742, in acquire
    cx = self._free_list.popleft()
IndexError: pop from an empty deque

During handling of the above exception, another exception occurred:

Traceback (most recent call last):
  File "/usr/local/lib/python3.6/dist-packages/flask/app.py", line 2292, in wsgi_app
    response = self.full_dispatch_request()
  File "/usr/local/lib/python3.6/dist-packages/flask/app.py", line 1815, in full_dispatch_request
    rv = self.handle_user_exception(e)
  File "/usr/local/lib/python3.6/dist-packages/flask/app.py", line 1718, in handle_user_exception
    reraise(exc_type, exc_value, tb)
  File "/usr/local/lib/python3.6/dist-packages/flask/_compat.py", line 35, in reraise
    raise value
  File "/usr/local/lib/python3.6/dist-packages/flask/app.py", line 1813, in full_dispatch_request
    rv = self.dispatch_request()
  File "/usr/local/lib/python3.6/dist-packages/flask/app.py", line 1799, in dispatch_request
    return self.view_functions[rule.endpoint](**req.view_args)
  File "/home/cartos.di.uminho.pt/LEI/cartos-master/app/base/routes.py", line 223, in login
    user = g.evaluate('match (x:User) where x._id=$v return x',v=_id)
  File "/usr/local/lib/python3.6/dist-packages/py2neo/database/__init__.py", line 498, in evaluate
    return self.auto().evaluate(cypher, parameters, **kwparameters)
  File "/usr/local/lib/python3.6/dist-packages/py2neo/database/work.py", line 170, in evaluate
    return self.run(cypher, parameters, **kwparameters).evaluate(0)
  File "/usr/local/lib/python3.6/dist-packages/py2neo/database/work.py", line 127, in run
    readonly=self.readonly)
  File "/usr/local/lib/python3.6/dist-packages/py2neo/client/__init__.py", line 1248, in auto_run
    cx = self.acquire(graph_name, readonly)
  File "/usr/local/lib/python3.6/dist-packages/py2neo/client/__init__.py", line 1075, in acquire
    cx = pool.acquire(force_reset=force_reset)
  File "/usr/local/lib/python3.6/dist-packages/py2neo/client/__init__.py", line 749, in acquire
    cx = self.connect()
  File "/usr/local/lib/python3.6/dist-packages/py2neo/client/__init__.py", line 702, in connect
    self._bytes_sent += cx.bytes_sent
  File "/usr/local/lib/python3.6/dist-packages/py2neo/client/__init__.py", line 184, in bytes_sent
    raise NotImplementedError
NotImplementedError
127.0.0.1 - - [21/Apr/2021 11:45:01] "POST /login HTTP/1.1" 500 -
Error on request:
Traceback (most recent call last):
  File "/usr/local/lib/python3.6/dist-packages/py2neo/client/__init__.py", line 742, in acquire
    cx = self._free_list.popleft()
IndexError: pop from an empty deque

During handling of the above exception, another exception occurred:

Traceback (most recent call last):
  File "/usr/local/lib/python3.6/dist-packages/flask/app.py", line 2292, in wsgi_app
    response = self.full_dispatch_request()
  File "/usr/local/lib/python3.6/dist-packages/flask/app.py", line 1815, in full_dispatch_request
    rv = self.handle_user_exception(e)
  File "/usr/local/lib/python3.6/dist-packages/flask/app.py", line 1718, in handle_user_exception
    reraise(exc_type, exc_value, tb)
  File "/usr/local/lib/python3.6/dist-packages/flask/_compat.py", line 35, in reraise
    raise value
  File "/usr/local/lib/python3.6/dist-packages/flask/app.py", line 1813, in full_dispatch_request
    rv = self.dispatch_request()
  File "/usr/local/lib/python3.6/dist-packages/flask/app.py", line 1799, in dispatch_request
    return self.view_functions[rule.endpoint](**req.view_args)
  File "/home/cartos.di.uminho.pt/LEI/cartos-master/app/base/routes.py", line 223, in login
    user = g.evaluate('match (x:User) where x._id=$v return x',v=_id)
  File "/usr/local/lib/python3.6/dist-packages/py2neo/database/__init__.py", line 498, in evaluate
    return self.auto().evaluate(cypher, parameters, **kwparameters)
  File "/usr/local/lib/python3.6/dist-packages/py2neo/database/work.py", line 170, in evaluate
    return self.run(cypher, parameters, **kwparameters).evaluate(0)
  File "/usr/local/lib/python3.6/dist-packages/py2neo/database/work.py", line 127, in run
    readonly=self.readonly)
  File "/usr/local/lib/python3.6/dist-packages/py2neo/client/__init__.py", line 1248, in auto_run
    cx = self.acquire(graph_name, readonly)
  File "/usr/local/lib/python3.6/dist-packages/py2neo/client/__init__.py", line 1075, in acquire
    cx = pool.acquire(force_reset=force_reset)
  File "/usr/local/lib/python3.6/dist-packages/py2neo/client/__init__.py", line 749, in acquire
    cx = self.connect()
  File "/usr/local/lib/python3.6/dist-packages/py2neo/client/__init__.py", line 702, in connect
    self._bytes_sent += cx.bytes_sent
  File "/usr/local/lib/python3.6/dist-packages/py2neo/client/__init__.py", line 184, in bytes_sent
    raise NotImplementedError
NotImplementedError

During handling of the above exception, another exception occurred:

Traceback (most recent call last):
  File "/usr/local/lib/python3.6/dist-packages/werkzeug/serving.py", line 302, in run_wsgi
    execute(self.server.app)
  File "/usr/local/lib/python3.6/dist-packages/werkzeug/serving.py", line 290, in execute
    application_iter = app(environ, start_response)
  File "/usr/local/lib/python3.6/dist-packages/flask/app.py", line 2309, in __call__
    return self.wsgi_app(environ, start_response)
  File "/usr/local/lib/python3.6/dist-packages/flask/app.py", line 2295, in wsgi_app
    response = self.handle_exception(e)
  File "/usr/local/lib/python3.6/dist-packages/flask/app.py", line 1748, in handle_exception
    return self.finalize_request(handler(e), from_error_handler=True)
  File "/home/cartos.di.uminho.pt/LEI/cartos-master/app/base/routes.py", line 274, in internal_error
    return render_template('errors/page_500.html'), 500
  File "/usr/local/lib/python3.6/dist-packages/flask/templating.py", line 133, in render_template
    ctx.app.update_template_context(context)
  File "/usr/local/lib/python3.6/dist-packages/flask/app.py", line 792, in update_template_context
    context.update(func())
  File "/usr/local/lib/python3.6/dist-packages/flask_login/utils.py", line 379, in _user_context_processor
    return dict(current_user=_get_user())
  File "/usr/local/lib/python3.6/dist-packages/flask_login/utils.py", line 346, in _get_user
    current_app.login_manager._load_user()
  File "/usr/local/lib/python3.6/dist-packages/flask_login/login_manager.py", line 303, in _load_user
    "Missing user_loader or request_loader. Refer to "
Exception: Missing user_loader or request_loader. Refer to http://flask-login.readthedocs.io/#how-it-works for more info.
127.0.0.1 - - [21/Apr/2021 11:45:03] "POST /login HTTP/1.1" 200 -
127.0.0.1 - - [22/Apr/2021 13:13:54] "GET /analise/foliosnames HTTP/1.1" 200 -
[2021-04-22 13:14:11,358] ERROR in app: Exception on /login [POST]
Traceback (most recent call last):
  File "/usr/local/lib/python3.6/dist-packages/py2neo/client/__init__.py", line 742, in acquire
    cx = self._free_list.popleft()
IndexError: pop from an empty deque

During handling of the above exception, another exception occurred:

Traceback (most recent call last):
  File "/usr/local/lib/python3.6/dist-packages/flask/app.py", line 2292, in wsgi_app
    response = self.full_dispatch_request()
  File "/usr/local/lib/python3.6/dist-packages/flask/app.py", line 1815, in full_dispatch_request
    rv = self.handle_user_exception(e)
  File "/usr/local/lib/python3.6/dist-packages/flask/app.py", line 1718, in handle_user_exception
    reraise(exc_type, exc_value, tb)
  File "/usr/local/lib/python3.6/dist-packages/flask/_compat.py", line 35, in reraise
    raise value
  File "/usr/local/lib/python3.6/dist-packages/flask/app.py", line 1813, in full_dispatch_request
    rv = self.dispatch_request()
  File "/usr/local/lib/python3.6/dist-packages/flask/app.py", line 1799, in dispatch_request
    return self.view_functions[rule.endpoint](**req.view_args)
  File "/home/cartos.di.uminho.pt/LEI/cartos-master/app/base/routes.py", line 223, in login
    user = g.evaluate('match (x:User) where x._id=$v return x',v=_id)
  File "/usr/local/lib/python3.6/dist-packages/py2neo/database/__init__.py", line 498, in evaluate
    return self.auto().evaluate(cypher, parameters, **kwparameters)
  File "/usr/local/lib/python3.6/dist-packages/py2neo/database/work.py", line 170, in evaluate
    return self.run(cypher, parameters, **kwparameters).evaluate(0)
  File "/usr/local/lib/python3.6/dist-packages/py2neo/database/work.py", line 127, in run
    readonly=self.readonly)
  File "/usr/local/lib/python3.6/dist-packages/py2neo/client/__init__.py", line 1248, in auto_run
    cx = self.acquire(graph_name, readonly)
  File "/usr/local/lib/python3.6/dist-packages/py2neo/client/__init__.py", line 1075, in acquire
    cx = pool.acquire(force_reset=force_reset)
  File "/usr/local/lib/python3.6/dist-packages/py2neo/client/__init__.py", line 749, in acquire
    cx = self.connect()
  File "/usr/local/lib/python3.6/dist-packages/py2neo/client/__init__.py", line 702, in connect
    self._bytes_sent += cx.bytes_sent
  File "/usr/local/lib/python3.6/dist-packages/py2neo/client/__init__.py", line 184, in bytes_sent
    raise NotImplementedError
NotImplementedError
127.0.0.1 - - [22/Apr/2021 13:14:11] "POST /login HTTP/1.1" 500 -
Error on request:
Traceback (most recent call last):
  File "/usr/local/lib/python3.6/dist-packages/py2neo/client/__init__.py", line 742, in acquire
    cx = self._free_list.popleft()
IndexError: pop from an empty deque

During handling of the above exception, another exception occurred:

Traceback (most recent call last):
  File "/usr/local/lib/python3.6/dist-packages/flask/app.py", line 2292, in wsgi_app
    response = self.full_dispatch_request()
  File "/usr/local/lib/python3.6/dist-packages/flask/app.py", line 1815, in full_dispatch_request
    rv = self.handle_user_exception(e)
  File "/usr/local/lib/python3.6/dist-packages/flask/app.py", line 1718, in handle_user_exception
    reraise(exc_type, exc_value, tb)
  File "/usr/local/lib/python3.6/dist-packages/flask/_compat.py", line 35, in reraise
    raise value
  File "/usr/local/lib/python3.6/dist-packages/flask/app.py", line 1813, in full_dispatch_request
    rv = self.dispatch_request()
  File "/usr/local/lib/python3.6/dist-packages/flask/app.py", line 1799, in dispatch_request
    return self.view_functions[rule.endpoint](**req.view_args)
  File "/home/cartos.di.uminho.pt/LEI/cartos-master/app/base/routes.py", line 223, in login
    user = g.evaluate('match (x:User) where x._id=$v return x',v=_id)
  File "/usr/local/lib/python3.6/dist-packages/py2neo/database/__init__.py", line 498, in evaluate
    return self.auto().evaluate(cypher, parameters, **kwparameters)
  File "/usr/local/lib/python3.6/dist-packages/py2neo/database/work.py", line 170, in evaluate
    return self.run(cypher, parameters, **kwparameters).evaluate(0)
  File "/usr/local/lib/python3.6/dist-packages/py2neo/database/work.py", line 127, in run
    readonly=self.readonly)
  File "/usr/local/lib/python3.6/dist-packages/py2neo/client/__init__.py", line 1248, in auto_run
    cx = self.acquire(graph_name, readonly)
  File "/usr/local/lib/python3.6/dist-packages/py2neo/client/__init__.py", line 1075, in acquire
    cx = pool.acquire(force_reset=force_reset)
  File "/usr/local/lib/python3.6/dist-packages/py2neo/client/__init__.py", line 749, in acquire
    cx = self.connect()
  File "/usr/local/lib/python3.6/dist-packages/py2neo/client/__init__.py", line 702, in connect
    self._bytes_sent += cx.bytes_sent
  File "/usr/local/lib/python3.6/dist-packages/py2neo/client/__init__.py", line 184, in bytes_sent
    raise NotImplementedError
NotImplementedError

During handling of the above exception, another exception occurred:

Traceback (most recent call last):
  File "/usr/local/lib/python3.6/dist-packages/werkzeug/serving.py", line 302, in run_wsgi
    execute(self.server.app)
  File "/usr/local/lib/python3.6/dist-packages/werkzeug/serving.py", line 290, in execute
    application_iter = app(environ, start_response)
  File "/usr/local/lib/python3.6/dist-packages/flask/app.py", line 2309, in __call__
    return self.wsgi_app(environ, start_response)
  File "/usr/local/lib/python3.6/dist-packages/flask/app.py", line 2295, in wsgi_app
    response = self.handle_exception(e)
  File "/usr/local/lib/python3.6/dist-packages/flask/app.py", line 1748, in handle_exception
    return self.finalize_request(handler(e), from_error_handler=True)
  File "/home/cartos.di.uminho.pt/LEI/cartos-master/app/base/routes.py", line 274, in internal_error
    return render_template('errors/page_500.html'), 500
  File "/usr/local/lib/python3.6/dist-packages/flask/templating.py", line 133, in render_template
    ctx.app.update_template_context(context)
  File "/usr/local/lib/python3.6/dist-packages/flask/app.py", line 792, in update_template_context
    context.update(func())
  File "/usr/local/lib/python3.6/dist-packages/flask_login/utils.py", line 379, in _user_context_processor
    return dict(current_user=_get_user())
  File "/usr/local/lib/python3.6/dist-packages/flask_login/utils.py", line 346, in _get_user
    current_app.login_manager._load_user()
  File "/usr/local/lib/python3.6/dist-packages/flask_login/login_manager.py", line 303, in _load_user
    "Missing user_loader or request_loader. Refer to "
Exception: Missing user_loader or request_loader. Refer to http://flask-login.readthedocs.io/#how-it-works for more info.
127.0.0.1 - - [22/Apr/2021 15:04:29] "GET /users HTTP/1.1" 404 -
127.0.0.1 - - [23/Apr/2021 22:05:45] "GET /analise/foliosnames HTTP/1.1" 200 -
127.0.0.1 - - [23/Apr/2021 22:05:51] "POST /login HTTP/1.1" 200 -
127.0.0.1 - - [23/Apr/2021 22:05:57] "POST /login HTTP/1.1" 200 -
127.0.0.1 - - [23/Apr/2021 22:08:25] "POST /login HTTP/1.1" 200 -
127.0.0.1 - - [23/Apr/2021 22:16:39] "POST /login HTTP/1.1" 200 -
127.0.0.1 - - [23/Apr/2021 22:20:10] "POST /login HTTP/1.1" 200 -
[2021-04-24 23:03:14,448] ERROR in app: Exception on /login [POST]
Traceback (most recent call last):
  File "/usr/local/lib/python3.6/dist-packages/py2neo/client/__init__.py", line 742, in acquire
    cx = self._free_list.popleft()
IndexError: pop from an empty deque

During handling of the above exception, another exception occurred:

Traceback (most recent call last):
  File "/usr/local/lib/python3.6/dist-packages/flask/app.py", line 2292, in wsgi_app
    response = self.full_dispatch_request()
  File "/usr/local/lib/python3.6/dist-packages/flask/app.py", line 1815, in full_dispatch_request
    rv = self.handle_user_exception(e)
  File "/usr/local/lib/python3.6/dist-packages/flask/app.py", line 1718, in handle_user_exception
    reraise(exc_type, exc_value, tb)
  File "/usr/local/lib/python3.6/dist-packages/flask/_compat.py", line 35, in reraise
    raise value
  File "/usr/local/lib/python3.6/dist-packages/flask/app.py", line 1813, in full_dispatch_request
    rv = self.dispatch_request()
  File "/usr/local/lib/python3.6/dist-packages/flask/app.py", line 1799, in dispatch_request
    return self.view_functions[rule.endpoint](**req.view_args)
  File "/home/cartos.di.uminho.pt/LEI/cartos-master/app/base/routes.py", line 223, in login
    user = g.evaluate('match (x:User) where x._id=$v return x',v=_id)
  File "/usr/local/lib/python3.6/dist-packages/py2neo/database/__init__.py", line 498, in evaluate
    return self.auto().evaluate(cypher, parameters, **kwparameters)
  File "/usr/local/lib/python3.6/dist-packages/py2neo/database/work.py", line 170, in evaluate
    return self.run(cypher, parameters, **kwparameters).evaluate(0)
  File "/usr/local/lib/python3.6/dist-packages/py2neo/database/work.py", line 127, in run
    readonly=self.readonly)
  File "/usr/local/lib/python3.6/dist-packages/py2neo/client/__init__.py", line 1248, in auto_run
    cx = self.acquire(graph_name, readonly)
  File "/usr/local/lib/python3.6/dist-packages/py2neo/client/__init__.py", line 1075, in acquire
    cx = pool.acquire(force_reset=force_reset)
  File "/usr/local/lib/python3.6/dist-packages/py2neo/client/__init__.py", line 749, in acquire
    cx = self.connect()
  File "/usr/local/lib/python3.6/dist-packages/py2neo/client/__init__.py", line 702, in connect
    self._bytes_sent += cx.bytes_sent
  File "/usr/local/lib/python3.6/dist-packages/py2neo/client/__init__.py", line 184, in bytes_sent
    raise NotImplementedError
NotImplementedError
127.0.0.1 - - [24/Apr/2021 23:03:14] "POST /login HTTP/1.1" 500 -
Error on request:
Traceback (most recent call last):
  File "/usr/local/lib/python3.6/dist-packages/py2neo/client/__init__.py", line 742, in acquire
    cx = self._free_list.popleft()
IndexError: pop from an empty deque

During handling of the above exception, another exception occurred:

Traceback (most recent call last):
  File "/usr/local/lib/python3.6/dist-packages/flask/app.py", line 2292, in wsgi_app
    response = self.full_dispatch_request()
  File "/usr/local/lib/python3.6/dist-packages/flask/app.py", line 1815, in full_dispatch_request
    rv = self.handle_user_exception(e)
  File "/usr/local/lib/python3.6/dist-packages/flask/app.py", line 1718, in handle_user_exception
    reraise(exc_type, exc_value, tb)
  File "/usr/local/lib/python3.6/dist-packages/flask/_compat.py", line 35, in reraise
    raise value
  File "/usr/local/lib/python3.6/dist-packages/flask/app.py", line 1813, in full_dispatch_request
    rv = self.dispatch_request()
  File "/usr/local/lib/python3.6/dist-packages/flask/app.py", line 1799, in dispatch_request
    return self.view_functions[rule.endpoint](**req.view_args)
  File "/home/cartos.di.uminho.pt/LEI/cartos-master/app/base/routes.py", line 223, in login
    user = g.evaluate('match (x:User) where x._id=$v return x',v=_id)
  File "/usr/local/lib/python3.6/dist-packages/py2neo/database/__init__.py", line 498, in evaluate
    return self.auto().evaluate(cypher, parameters, **kwparameters)
  File "/usr/local/lib/python3.6/dist-packages/py2neo/database/work.py", line 170, in evaluate
    return self.run(cypher, parameters, **kwparameters).evaluate(0)
  File "/usr/local/lib/python3.6/dist-packages/py2neo/database/work.py", line 127, in run
    readonly=self.readonly)
  File "/usr/local/lib/python3.6/dist-packages/py2neo/client/__init__.py", line 1248, in auto_run
    cx = self.acquire(graph_name, readonly)
  File "/usr/local/lib/python3.6/dist-packages/py2neo/client/__init__.py", line 1075, in acquire
    cx = pool.acquire(force_reset=force_reset)
  File "/usr/local/lib/python3.6/dist-packages/py2neo/client/__init__.py", line 749, in acquire
    cx = self.connect()
  File "/usr/local/lib/python3.6/dist-packages/py2neo/client/__init__.py", line 702, in connect
    self._bytes_sent += cx.bytes_sent
  File "/usr/local/lib/python3.6/dist-packages/py2neo/client/__init__.py", line 184, in bytes_sent
    raise NotImplementedError
NotImplementedError

During handling of the above exception, another exception occurred:

Traceback (most recent call last):
  File "/usr/local/lib/python3.6/dist-packages/werkzeug/serving.py", line 302, in run_wsgi
    execute(self.server.app)
  File "/usr/local/lib/python3.6/dist-packages/werkzeug/serving.py", line 290, in execute
    application_iter = app(environ, start_response)
  File "/usr/local/lib/python3.6/dist-packages/flask/app.py", line 2309, in __call__
    return self.wsgi_app(environ, start_response)
  File "/usr/local/lib/python3.6/dist-packages/flask/app.py", line 2295, in wsgi_app
    response = self.handle_exception(e)
  File "/usr/local/lib/python3.6/dist-packages/flask/app.py", line 1748, in handle_exception
    return self.finalize_request(handler(e), from_error_handler=True)
  File "/home/cartos.di.uminho.pt/LEI/cartos-master/app/base/routes.py", line 274, in internal_error
    return render_template('errors/page_500.html'), 500
  File "/usr/local/lib/python3.6/dist-packages/flask/templating.py", line 133, in render_template
    ctx.app.update_template_context(context)
  File "/usr/local/lib/python3.6/dist-packages/flask/app.py", line 792, in update_template_context
    context.update(func())
  File "/usr/local/lib/python3.6/dist-packages/flask_login/utils.py", line 379, in _user_context_processor
    return dict(current_user=_get_user())
  File "/usr/local/lib/python3.6/dist-packages/flask_login/utils.py", line 346, in _get_user
    current_app.login_manager._load_user()
  File "/usr/local/lib/python3.6/dist-packages/flask_login/login_manager.py", line 303, in _load_user
    "Missing user_loader or request_loader. Refer to "
Exception: Missing user_loader or request_loader. Refer to http://flask-login.readthedocs.io/#how-it-works for more info.
127.0.0.1 - - [24/Apr/2021 23:03:17] "POST /login HTTP/1.1" 200 -
127.0.0.1 - - [24/Apr/2021 23:03:25] "POST /login HTTP/1.1" 200 -
127.0.0.1 - - [24/Apr/2021 23:03:32] "POST /login HTTP/1.1" 200 -
127.0.0.1 - - [24/Apr/2021 23:03:39] "POST /login HTTP/1.1" 200 -
127.0.0.1 - - [24/Apr/2021 23:03:44] "POST /login HTTP/1.1" 200 -
127.0.0.1 - - [24/Apr/2021 23:04:11] "POST /login HTTP/1.1" 200 -
127.0.0.1 - - [24/Apr/2021 23:04:26] "POST /login HTTP/1.1" 200 -
127.0.0.1 - - [24/Apr/2021 23:04:33] "POST /login HTTP/1.1" 200 -
127.0.0.1 - - [24/Apr/2021 23:14:21] "POST /login HTTP/1.1" 200 -
127.0.0.1 - - [24/Apr/2021 23:25:40] "GET /login HTTP/1.1" 405 -
127.0.0.1 - - [24/Apr/2021 23:26:28] "GET /folios HTTP/1.1" 404 -
127.0.0.1 - - [24/Apr/2021 23:35:34] "GET /analise/foliosnames HTTP/1.1" 200 -
127.0.0.1 - - [24/Apr/2021 23:35:38] "GET /analise/pesquisa?pesquisa=Braga&selectedFolio=Todos&tipo=texto&versao=todas&resultado=periodo HTTP/1.1" 200 -
127.0.0.1 - - [24/Apr/2021 23:54:09] "GET /analise/foliosnames HTTP/1.1" 200 -
127.0.0.1 - - [24/Apr/2021 23:54:16] "POST /login HTTP/1.1" 200 -
127.0.0.1 - - [24/Apr/2021 23:54:27] "POST /login HTTP/1.1" 200 -
127.0.0.1 - - [24/Apr/2021 23:54:34] "POST /login HTTP/1.1" 200 -
127.0.0.1 - - [24/Apr/2021 23:54:40] "POST /login HTTP/1.1" 200 -
127.0.0.1 - - [24/Apr/2021 23:55:23] "POST /login HTTP/1.1" 200 -
127.0.0.1 - - [24/Apr/2021 23:56:20] "POST /login HTTP/1.1" 200 -
127.0.0.1 - - [24/Apr/2021 23:56:54] "POST /login HTTP/1.1" 200 -
127.0.0.1 - - [25/Apr/2021 00:07:50] "GET / HTTP/1.1" 302 -
[2021-04-25 00:07:50,556] ERROR in app: Exception on /home [GET]
Traceback (most recent call last):
  File "/usr/local/lib/python3.6/dist-packages/flask/app.py", line 2292, in wsgi_app
    response = self.full_dispatch_request()
  File "/usr/local/lib/python3.6/dist-packages/flask/app.py", line 1815, in full_dispatch_request
    rv = self.handle_user_exception(e)
  File "/usr/local/lib/python3.6/dist-packages/flask/app.py", line 1718, in handle_user_exception
    reraise(exc_type, exc_value, tb)
  File "/usr/local/lib/python3.6/dist-packages/flask/_compat.py", line 35, in reraise
    raise value
  File "/usr/local/lib/python3.6/dist-packages/flask/app.py", line 1813, in full_dispatch_request
    rv = self.dispatch_request()
  File "/usr/local/lib/python3.6/dist-packages/flask/app.py", line 1799, in dispatch_request
    return self.view_functions[rule.endpoint](**req.view_args)
  File "/home/cartos.di.uminho.pt/LEI/cartos-master/app/base/routes.py", line 42, in pesquisa
    return render_template('pesquisa/pesquisa.html',folios=folios)
  File "/usr/local/lib/python3.6/dist-packages/flask/templating.py", line 133, in render_template
    ctx.app.update_template_context(context)
  File "/usr/local/lib/python3.6/dist-packages/flask/app.py", line 792, in update_template_context
    context.update(func())
  File "/usr/local/lib/python3.6/dist-packages/flask_login/utils.py", line 379, in _user_context_processor
    return dict(current_user=_get_user())
  File "/usr/local/lib/python3.6/dist-packages/flask_login/utils.py", line 346, in _get_user
    current_app.login_manager._load_user()
  File "/usr/local/lib/python3.6/dist-packages/flask_login/login_manager.py", line 303, in _load_user
    "Missing user_loader or request_loader. Refer to "
Exception: Missing user_loader or request_loader. Refer to http://flask-login.readthedocs.io/#how-it-works for more info.
127.0.0.1 - - [25/Apr/2021 00:07:50] "GET /home HTTP/1.1" 500 -
Error on request:
Traceback (most recent call last):
  File "/usr/local/lib/python3.6/dist-packages/flask/app.py", line 2292, in wsgi_app
    response = self.full_dispatch_request()
  File "/usr/local/lib/python3.6/dist-packages/flask/app.py", line 1815, in full_dispatch_request
    rv = self.handle_user_exception(e)
  File "/usr/local/lib/python3.6/dist-packages/flask/app.py", line 1718, in handle_user_exception
    reraise(exc_type, exc_value, tb)
  File "/usr/local/lib/python3.6/dist-packages/flask/_compat.py", line 35, in reraise
    raise value
  File "/usr/local/lib/python3.6/dist-packages/flask/app.py", line 1813, in full_dispatch_request
    rv = self.dispatch_request()
  File "/usr/local/lib/python3.6/dist-packages/flask/app.py", line 1799, in dispatch_request
    return self.view_functions[rule.endpoint](**req.view_args)
  File "/home/cartos.di.uminho.pt/LEI/cartos-master/app/base/routes.py", line 42, in pesquisa
    return render_template('pesquisa/pesquisa.html',folios=folios)
  File "/usr/local/lib/python3.6/dist-packages/flask/templating.py", line 133, in render_template
    ctx.app.update_template_context(context)
  File "/usr/local/lib/python3.6/dist-packages/flask/app.py", line 792, in update_template_context
    context.update(func())
  File "/usr/local/lib/python3.6/dist-packages/flask_login/utils.py", line 379, in _user_context_processor
    return dict(current_user=_get_user())
  File "/usr/local/lib/python3.6/dist-packages/flask_login/utils.py", line 346, in _get_user
    current_app.login_manager._load_user()
  File "/usr/local/lib/python3.6/dist-packages/flask_login/login_manager.py", line 303, in _load_user
    "Missing user_loader or request_loader. Refer to "
Exception: Missing user_loader or request_loader. Refer to http://flask-login.readthedocs.io/#how-it-works for more info.

During handling of the above exception, another exception occurred:

Traceback (most recent call last):
  File "/usr/local/lib/python3.6/dist-packages/werkzeug/serving.py", line 302, in run_wsgi
    execute(self.server.app)
  File "/usr/local/lib/python3.6/dist-packages/werkzeug/serving.py", line 290, in execute
    application_iter = app(environ, start_response)
  File "/usr/local/lib/python3.6/dist-packages/flask/app.py", line 2309, in __call__
    return self.wsgi_app(environ, start_response)
  File "/usr/local/lib/python3.6/dist-packages/flask/app.py", line 2295, in wsgi_app
    response = self.handle_exception(e)
  File "/usr/local/lib/python3.6/dist-packages/flask/app.py", line 1748, in handle_exception
    return self.finalize_request(handler(e), from_error_handler=True)
  File "/home/cartos.di.uminho.pt/LEI/cartos-master/app/base/routes.py", line 274, in internal_error
    return render_template('errors/page_500.html'), 500
  File "/usr/local/lib/python3.6/dist-packages/flask/templating.py", line 133, in render_template
    ctx.app.update_template_context(context)
  File "/usr/local/lib/python3.6/dist-packages/flask/app.py", line 792, in update_template_context
    context.update(func())
  File "/usr/local/lib/python3.6/dist-packages/flask_login/utils.py", line 379, in _user_context_processor
    return dict(current_user=_get_user())
  File "/usr/local/lib/python3.6/dist-packages/flask_login/utils.py", line 346, in _get_user
    current_app.login_manager._load_user()
  File "/usr/local/lib/python3.6/dist-packages/flask_login/login_manager.py", line 303, in _load_user
    "Missing user_loader or request_loader. Refer to "
Exception: Missing user_loader or request_loader. Refer to http://flask-login.readthedocs.io/#how-it-works for more info.
127.0.0.1 - - [25/Apr/2021 00:07:50] "GET /favicon.ico HTTP/1.1" 404 -
[2021-04-25 00:30:22,919] ERROR in app: Exception on /login [POST]
Traceback (most recent call last):
  File "/usr/local/lib/python3.6/dist-packages/py2neo/client/__init__.py", line 742, in acquire
    cx = self._free_list.popleft()
IndexError: pop from an empty deque

During handling of the above exception, another exception occurred:

Traceback (most recent call last):
  File "/usr/local/lib/python3.6/dist-packages/flask/app.py", line 2292, in wsgi_app
    response = self.full_dispatch_request()
  File "/usr/local/lib/python3.6/dist-packages/flask/app.py", line 1815, in full_dispatch_request
    rv = self.handle_user_exception(e)
  File "/usr/local/lib/python3.6/dist-packages/flask/app.py", line 1718, in handle_user_exception
    reraise(exc_type, exc_value, tb)
  File "/usr/local/lib/python3.6/dist-packages/flask/_compat.py", line 35, in reraise
    raise value
  File "/usr/local/lib/python3.6/dist-packages/flask/app.py", line 1813, in full_dispatch_request
    rv = self.dispatch_request()
  File "/usr/local/lib/python3.6/dist-packages/flask/app.py", line 1799, in dispatch_request
    return self.view_functions[rule.endpoint](**req.view_args)
  File "/home/cartos.di.uminho.pt/LEI/cartos-master/app/base/routes.py", line 223, in login
    user = g.evaluate('match (x:User) where x._id=$v return x',v=_id)
  File "/usr/local/lib/python3.6/dist-packages/py2neo/database/__init__.py", line 498, in evaluate
    return self.auto().evaluate(cypher, parameters, **kwparameters)
  File "/usr/local/lib/python3.6/dist-packages/py2neo/database/work.py", line 170, in evaluate
    return self.run(cypher, parameters, **kwparameters).evaluate(0)
  File "/usr/local/lib/python3.6/dist-packages/py2neo/database/work.py", line 127, in run
    readonly=self.readonly)
  File "/usr/local/lib/python3.6/dist-packages/py2neo/client/__init__.py", line 1248, in auto_run
    cx = self.acquire(graph_name, readonly)
  File "/usr/local/lib/python3.6/dist-packages/py2neo/client/__init__.py", line 1075, in acquire
    cx = pool.acquire(force_reset=force_reset)
  File "/usr/local/lib/python3.6/dist-packages/py2neo/client/__init__.py", line 749, in acquire
    cx = self.connect()
  File "/usr/local/lib/python3.6/dist-packages/py2neo/client/__init__.py", line 702, in connect
    self._bytes_sent += cx.bytes_sent
  File "/usr/local/lib/python3.6/dist-packages/py2neo/client/__init__.py", line 184, in bytes_sent
    raise NotImplementedError
NotImplementedError
127.0.0.1 - - [25/Apr/2021 00:30:22] "POST /login HTTP/1.1" 500 -
Error on request:
Traceback (most recent call last):
  File "/usr/local/lib/python3.6/dist-packages/py2neo/client/__init__.py", line 742, in acquire
    cx = self._free_list.popleft()
IndexError: pop from an empty deque

During handling of the above exception, another exception occurred:

Traceback (most recent call last):
  File "/usr/local/lib/python3.6/dist-packages/flask/app.py", line 2292, in wsgi_app
    response = self.full_dispatch_request()
  File "/usr/local/lib/python3.6/dist-packages/flask/app.py", line 1815, in full_dispatch_request
    rv = self.handle_user_exception(e)
  File "/usr/local/lib/python3.6/dist-packages/flask/app.py", line 1718, in handle_user_exception
    reraise(exc_type, exc_value, tb)
  File "/usr/local/lib/python3.6/dist-packages/flask/_compat.py", line 35, in reraise
    raise value
  File "/usr/local/lib/python3.6/dist-packages/flask/app.py", line 1813, in full_dispatch_request
    rv = self.dispatch_request()
  File "/usr/local/lib/python3.6/dist-packages/flask/app.py", line 1799, in dispatch_request
    return self.view_functions[rule.endpoint](**req.view_args)
  File "/home/cartos.di.uminho.pt/LEI/cartos-master/app/base/routes.py", line 223, in login
    user = g.evaluate('match (x:User) where x._id=$v return x',v=_id)
  File "/usr/local/lib/python3.6/dist-packages/py2neo/database/__init__.py", line 498, in evaluate
    return self.auto().evaluate(cypher, parameters, **kwparameters)
  File "/usr/local/lib/python3.6/dist-packages/py2neo/database/work.py", line 170, in evaluate
    return self.run(cypher, parameters, **kwparameters).evaluate(0)
  File "/usr/local/lib/python3.6/dist-packages/py2neo/database/work.py", line 127, in run
    readonly=self.readonly)
  File "/usr/local/lib/python3.6/dist-packages/py2neo/client/__init__.py", line 1248, in auto_run
    cx = self.acquire(graph_name, readonly)
  File "/usr/local/lib/python3.6/dist-packages/py2neo/client/__init__.py", line 1075, in acquire
    cx = pool.acquire(force_reset=force_reset)
  File "/usr/local/lib/python3.6/dist-packages/py2neo/client/__init__.py", line 749, in acquire
    cx = self.connect()
  File "/usr/local/lib/python3.6/dist-packages/py2neo/client/__init__.py", line 702, in connect
    self._bytes_sent += cx.bytes_sent
  File "/usr/local/lib/python3.6/dist-packages/py2neo/client/__init__.py", line 184, in bytes_sent
    raise NotImplementedError
NotImplementedError

During handling of the above exception, another exception occurred:

Traceback (most recent call last):
  File "/usr/local/lib/python3.6/dist-packages/werkzeug/serving.py", line 302, in run_wsgi
    execute(self.server.app)
  File "/usr/local/lib/python3.6/dist-packages/werkzeug/serving.py", line 290, in execute
    application_iter = app(environ, start_response)
  File "/usr/local/lib/python3.6/dist-packages/flask/app.py", line 2309, in __call__
    return self.wsgi_app(environ, start_response)
  File "/usr/local/lib/python3.6/dist-packages/flask/app.py", line 2295, in wsgi_app
    response = self.handle_exception(e)
  File "/usr/local/lib/python3.6/dist-packages/flask/app.py", line 1748, in handle_exception
    return self.finalize_request(handler(e), from_error_handler=True)
  File "/home/cartos.di.uminho.pt/LEI/cartos-master/app/base/routes.py", line 274, in internal_error
    return render_template('errors/page_500.html'), 500
  File "/usr/local/lib/python3.6/dist-packages/flask/templating.py", line 133, in render_template
    ctx.app.update_template_context(context)
  File "/usr/local/lib/python3.6/dist-packages/flask/app.py", line 792, in update_template_context
    context.update(func())
  File "/usr/local/lib/python3.6/dist-packages/flask_login/utils.py", line 379, in _user_context_processor
    return dict(current_user=_get_user())
  File "/usr/local/lib/python3.6/dist-packages/flask_login/utils.py", line 346, in _get_user
    current_app.login_manager._load_user()
  File "/usr/local/lib/python3.6/dist-packages/flask_login/login_manager.py", line 303, in _load_user
    "Missing user_loader or request_loader. Refer to "
Exception: Missing user_loader or request_loader. Refer to http://flask-login.readthedocs.io/#how-it-works for more info.
127.0.0.1 - - [25/Apr/2021 00:30:26] "POST /login HTTP/1.1" 200 -
127.0.0.1 - - [25/Apr/2021 00:30:50] "POST /login HTTP/1.1" 200 -
127.0.0.1 - - [25/Apr/2021 00:32:18] "POST /login HTTP/1.1" 200 -
127.0.0.1 - - [25/Apr/2021 00:32:27] "POST /login HTTP/1.1" 200 -
127.0.0.1 - - [25/Apr/2021 00:33:20] "POST /login HTTP/1.1" 200 -
127.0.0.1 - - [25/Apr/2021 00:33:27] "POST /login HTTP/1.1" 200 -
127.0.0.1 - - [25/Apr/2021 00:33:37] "POST /login HTTP/1.1" 200 -
[2021-04-25 00:34:32,773] ERROR in app: Exception on /users/pedidos/registar [POST]
Traceback (most recent call last):
  File "/usr/local/lib/python3.6/dist-packages/py2neo/client/__init__.py", line 742, in acquire
    cx = self._free_list.popleft()
IndexError: pop from an empty deque

During handling of the above exception, another exception occurred:

Traceback (most recent call last):
  File "/usr/local/lib/python3.6/dist-packages/flask/app.py", line 2292, in wsgi_app
    response = self.full_dispatch_request()
  File "/usr/local/lib/python3.6/dist-packages/flask/app.py", line 1815, in full_dispatch_request
    rv = self.handle_user_exception(e)
  File "/usr/local/lib/python3.6/dist-packages/flask/app.py", line 1718, in handle_user_exception
    reraise(exc_type, exc_value, tb)
  File "/usr/local/lib/python3.6/dist-packages/flask/_compat.py", line 35, in reraise
    raise value
  File "/usr/local/lib/python3.6/dist-packages/flask/app.py", line 1813, in full_dispatch_request
    rv = self.dispatch_request()
  File "/usr/local/lib/python3.6/dist-packages/flask/app.py", line 1799, in dispatch_request
    return self.view_functions[rule.endpoint](**req.view_args)
  File "/home/cartos.di.uminho.pt/LEI/cartos-master/app/users/routes.py", line 275, in route_template_registar_pedido
    existeU = g.evaluate('match (x:User) where x.username=$v return x',v=username)
  File "/usr/local/lib/python3.6/dist-packages/py2neo/database/__init__.py", line 498, in evaluate
    return self.auto().evaluate(cypher, parameters, **kwparameters)
  File "/usr/local/lib/python3.6/dist-packages/py2neo/database/work.py", line 170, in evaluate
    return self.run(cypher, parameters, **kwparameters).evaluate(0)
  File "/usr/local/lib/python3.6/dist-packages/py2neo/database/work.py", line 127, in run
    readonly=self.readonly)
  File "/usr/local/lib/python3.6/dist-packages/py2neo/client/__init__.py", line 1248, in auto_run
    cx = self.acquire(graph_name, readonly)
  File "/usr/local/lib/python3.6/dist-packages/py2neo/client/__init__.py", line 1075, in acquire
    cx = pool.acquire(force_reset=force_reset)
  File "/usr/local/lib/python3.6/dist-packages/py2neo/client/__init__.py", line 749, in acquire
    cx = self.connect()
  File "/usr/local/lib/python3.6/dist-packages/py2neo/client/__init__.py", line 702, in connect
    self._bytes_sent += cx.bytes_sent
  File "/usr/local/lib/python3.6/dist-packages/py2neo/client/__init__.py", line 184, in bytes_sent
    raise NotImplementedError
NotImplementedError
127.0.0.1 - - [25/Apr/2021 00:34:32] "POST /users/pedidos/registar HTTP/1.1" 500 -
127.0.0.1 - - [25/Apr/2021 00:34:44] "POST /users/pedidos/registar HTTP/1.1" 200 -
127.0.0.1 - - [25/Apr/2021 00:35:05] "POST /login HTTP/1.1" 200 -
127.0.0.1 - - [25/Apr/2021 00:35:05] "GET /folios/folios?nome=xkstr HTTP/1.1" 404 -
127.0.0.1 - - [25/Apr/2021 00:35:05] "GET /users/users?nome=xkstr HTTP/1.1" 401 -
127.0.0.1 - - [25/Apr/2021 00:35:05] "GET /users/foto/xkstr?seed=1619307305352 HTTP/1.1" 401 -
127.0.0.1 - - [25/Apr/2021 00:35:05] "GET /users/foto/xkstr HTTP/1.1" 200 -
127.0.0.1 - - [25/Apr/2021 00:35:31] "GET /users/foto/xkstr?seed=1619307331013 HTTP/1.1" 200 -
127.0.0.1 - - [25/Apr/2021 00:35:31] "GET /users/users?nome=admin HTTP/1.1" 200 -
127.0.0.1 - - [25/Apr/2021 00:36:32] "GET /users/foto/xkstr?seed=1619307391974 HTTP/1.1" 200 -
127.0.0.1 - - [25/Apr/2021 00:36:32] "GET /users/active?nome=xkstr HTTP/1.1" 200 -
127.0.0.1 - - [25/Apr/2021 00:36:35] "GET /users/pedidos?nome=admin HTTP/1.1" 200 -
127.0.0.1 - - [25/Apr/2021 00:36:35] "GET /users/foto/xkstr?seed=1619307395818 HTTP/1.1" 200 -
127.0.0.1 - - [25/Apr/2021 00:36:40] "GET /users/foto/xkstr?seed=1619307400718 HTTP/1.1" 200 -
127.0.0.1 - - [25/Apr/2021 00:36:41] "GET /users/history?nome=xkstr HTTP/1.1" 200 -
127.0.0.1 - - [25/Apr/2021 00:36:45] "GET /users/foto/xkstr?seed=1619307405378 HTTP/1.1" 200 -
127.0.0.1 - - [25/Apr/2021 00:36:45] "GET /users/users?nome=admin HTTP/1.1" 200 -
127.0.0.1 - - [25/Apr/2021 00:36:55] "GET /users/active?nome=xkstr HTTP/1.1" 200 -
127.0.0.1 - - [25/Apr/2021 00:36:55] "GET /users/foto/xkstr?seed=1619307415418 HTTP/1.1" 200 -
127.0.0.1 - - [25/Apr/2021 00:37:00] "GET /users/pedidos?nome=admin HTTP/1.1" 200 -
127.0.0.1 - - [25/Apr/2021 00:37:00] "GET /users/foto/xkstr?seed=1619307420062 HTTP/1.1" 200 -
127.0.0.1 - - [25/Apr/2021 00:37:02] "GET /users/users?nome=admin HTTP/1.1" 200 -
127.0.0.1 - - [25/Apr/2021 00:37:02] "GET /users/foto/xkstr?seed=1619307422272 HTTP/1.1" 200 -
127.0.0.1 - - [25/Apr/2021 00:37:10] "GET /users/foto/xkstr?seed=1619307430156 HTTP/1.1" 200 -
127.0.0.1 - - [25/Apr/2021 00:37:10] "GET /users/foto/xkstr?seed=1619307430158 HTTP/1.1" 200 -
127.0.0.1 - - [25/Apr/2021 00:37:22] "GET /folios/folios?nome=xkstr HTTP/1.1" 404 -
127.0.0.1 - - [25/Apr/2021 00:37:22] "GET /users/foto/xkstr?seed=1619307442410 HTTP/1.1" 200 -
127.0.0.1 - - [25/Apr/2021 00:37:22] "GET /users/users?nome=xkstr HTTP/1.1" 200 -
127.0.0.1 - - [25/Apr/2021 00:37:25] "GET /folios/folios?nome=xkstr HTTP/1.1" 404 -
127.0.0.1 - - [25/Apr/2021 00:37:25] "GET /users/foto/xkstr?seed=1619307445209 HTTP/1.1" 200 -
127.0.0.1 - - [25/Apr/2021 00:37:38] "GET /folios/index?nome=xkstr HTTP/1.1" 404 -
127.0.0.1 - - [25/Apr/2021 00:37:38] "GET /users/foto/xkstr?seed=1619307458317 HTTP/1.1" 200 -
127.0.0.1 - - [25/Apr/2021 00:37:40] "GET /folios/folios?nome=xkstr HTTP/1.1" 404 -
127.0.0.1 - - [25/Apr/2021 00:37:41] "GET /users/foto/xkstr?seed=1619307460937 HTTP/1.1" 200 -
127.0.0.1 - - [25/Apr/2021 00:37:50] "GET /folios/folios?nome=xkstr HTTP/1.1" 404 -
127.0.0.1 - - [25/Apr/2021 00:37:50] "GET /users/foto/xkstr?seed=1619307470227 HTTP/1.1" 200 -
127.0.0.1 - - [25/Apr/2021 00:38:28] "GET /folios/index?nome=xkstr HTTP/1.1" 404 -
127.0.0.1 - - [25/Apr/2021 00:38:28] "GET /users/foto/xkstr?seed=1619307508807 HTTP/1.1" 200 -
127.0.0.1 - - [25/Apr/2021 00:38:47] "GET /analise/foliosnames HTTP/1.1" 200 -
127.0.0.1 - - [25/Apr/2021 00:38:47] "GET /users/foto/xkstr?seed=1619307526972 HTTP/1.1" 200 -
127.0.0.1 - - [25/Apr/2021 00:38:51] "GET /users/foto/xkstr?seed=1619307531680 HTTP/1.1" 200 -
127.0.0.1 - - [25/Apr/2021 00:38:51] "GET /users/users?nome=admin HTTP/1.1" 200 -
127.0.0.1 - - [25/Apr/2021 00:39:04] "GET /users/foto/xkstr?seed=1619307544331 HTTP/1.1" 200 -
127.0.0.1 - - [25/Apr/2021 00:39:04] "GET /users/foto/xkstr?seed=1619307544328 HTTP/1.1" 200 -
127.0.0.1 - - [25/Apr/2021 00:39:07] "GET /users/users?nome=admin HTTP/1.1" 200 -
127.0.0.1 - - [25/Apr/2021 00:39:07] "GET /users/foto/xkstr?seed=1619307547580 HTTP/1.1" 200 -
 * Serving Flask app "tommi.py"
 * Environment: production
   WARNING: Do not use the development server in a production environment.
   Use a production WSGI server instead.
 * Debug mode: off
 * Running on http://127.0.0.1:5000/ (Press CTRL+C to quit)
127.0.0.1 - - [25/Apr/2021 19:45:53] "GET /analise/foliosnames HTTP/1.1" 200 -
127.0.0.1 - - [25/Apr/2021 19:46:38] "OPTIONS /login HTTP/1.1" 200 -
127.0.0.1 - - [25/Apr/2021 19:46:38] "POST /login HTTP/1.1" 200 -
127.0.0.1 - - [25/Apr/2021 19:46:38] "OPTIONS /users/users?nome=obelo HTTP/1.1" 200 -
127.0.0.1 - - [25/Apr/2021 19:46:38] "OPTIONS /folios/folios?nome=obelo HTTP/1.1" 404 -
127.0.0.1 - - [25/Apr/2021 19:46:38] "OPTIONS /users/foto/obelo?seed=1619376398259 HTTP/1.1" 200 -
127.0.0.1 - - [25/Apr/2021 19:46:38] "OPTIONS /users/foto/obelo HTTP/1.1" 200 -
127.0.0.1 - - [25/Apr/2021 19:46:38] "GET /users/users?nome=obelo HTTP/1.1" 200 -
127.0.0.1 - - [25/Apr/2021 19:46:38] "GET /users/foto/obelo?seed=1619376398259 HTTP/1.1" 200 -
127.0.0.1 - - [25/Apr/2021 21:30:18] "GET /login HTTP/1.1" 405 -
127.0.0.1 - - [25/Apr/2021 21:59:53] "GET /analise/foliosnames HTTP/1.1" 200 -
127.0.0.1 - - [25/Apr/2021 22:00:04] "GET /login HTTP/1.1" 405 -
127.0.0.1 - - [25/Apr/2021 22:05:21] "GET /analise/foliosnames HTTP/1.1" 200 -
[2021-04-25 22:05:27,460] ERROR in app: Exception on /login [POST]
Traceback (most recent call last):
  File "/usr/local/lib/python3.6/dist-packages/py2neo/client/__init__.py", line 742, in acquire
    cx = self._free_list.popleft()
IndexError: pop from an empty deque

During handling of the above exception, another exception occurred:

Traceback (most recent call last):
  File "/usr/local/lib/python3.6/dist-packages/flask/app.py", line 2292, in wsgi_app
    response = self.full_dispatch_request()
  File "/usr/local/lib/python3.6/dist-packages/flask/app.py", line 1815, in full_dispatch_request
    rv = self.handle_user_exception(e)
  File "/usr/local/lib/python3.6/dist-packages/flask/app.py", line 1718, in handle_user_exception
    reraise(exc_type, exc_value, tb)
  File "/usr/local/lib/python3.6/dist-packages/flask/_compat.py", line 35, in reraise
    raise value
  File "/usr/local/lib/python3.6/dist-packages/flask/app.py", line 1813, in full_dispatch_request
    rv = self.dispatch_request()
  File "/usr/local/lib/python3.6/dist-packages/flask/app.py", line 1799, in dispatch_request
    return self.view_functions[rule.endpoint](**req.view_args)
  File "/home/cartos.di.uminho.pt/LEI/cartos-master/app/base/routes.py", line 223, in login
    user = g.evaluate('match (x:User) where x._id=$v return x',v=_id)
  File "/usr/local/lib/python3.6/dist-packages/py2neo/database/__init__.py", line 498, in evaluate
    return self.auto().evaluate(cypher, parameters, **kwparameters)
  File "/usr/local/lib/python3.6/dist-packages/py2neo/database/work.py", line 170, in evaluate
    return self.run(cypher, parameters, **kwparameters).evaluate(0)
  File "/usr/local/lib/python3.6/dist-packages/py2neo/database/work.py", line 127, in run
    readonly=self.readonly)
  File "/usr/local/lib/python3.6/dist-packages/py2neo/client/__init__.py", line 1248, in auto_run
    cx = self.acquire(graph_name, readonly)
  File "/usr/local/lib/python3.6/dist-packages/py2neo/client/__init__.py", line 1075, in acquire
    cx = pool.acquire(force_reset=force_reset)
  File "/usr/local/lib/python3.6/dist-packages/py2neo/client/__init__.py", line 749, in acquire
    cx = self.connect()
  File "/usr/local/lib/python3.6/dist-packages/py2neo/client/__init__.py", line 702, in connect
    self._bytes_sent += cx.bytes_sent
  File "/usr/local/lib/python3.6/dist-packages/py2neo/client/__init__.py", line 184, in bytes_sent
    raise NotImplementedError
NotImplementedError
127.0.0.1 - - [25/Apr/2021 22:05:27] "POST /login HTTP/1.1" 500 -
Error on request:
Traceback (most recent call last):
  File "/usr/local/lib/python3.6/dist-packages/py2neo/client/__init__.py", line 742, in acquire
    cx = self._free_list.popleft()
IndexError: pop from an empty deque

During handling of the above exception, another exception occurred:

Traceback (most recent call last):
  File "/usr/local/lib/python3.6/dist-packages/flask/app.py", line 2292, in wsgi_app
    response = self.full_dispatch_request()
  File "/usr/local/lib/python3.6/dist-packages/flask/app.py", line 1815, in full_dispatch_request
    rv = self.handle_user_exception(e)
  File "/usr/local/lib/python3.6/dist-packages/flask/app.py", line 1718, in handle_user_exception
    reraise(exc_type, exc_value, tb)
  File "/usr/local/lib/python3.6/dist-packages/flask/_compat.py", line 35, in reraise
    raise value
  File "/usr/local/lib/python3.6/dist-packages/flask/app.py", line 1813, in full_dispatch_request
    rv = self.dispatch_request()
  File "/usr/local/lib/python3.6/dist-packages/flask/app.py", line 1799, in dispatch_request
    return self.view_functions[rule.endpoint](**req.view_args)
  File "/home/cartos.di.uminho.pt/LEI/cartos-master/app/base/routes.py", line 223, in login
    user = g.evaluate('match (x:User) where x._id=$v return x',v=_id)
  File "/usr/local/lib/python3.6/dist-packages/py2neo/database/__init__.py", line 498, in evaluate
    return self.auto().evaluate(cypher, parameters, **kwparameters)
  File "/usr/local/lib/python3.6/dist-packages/py2neo/database/work.py", line 170, in evaluate
    return self.run(cypher, parameters, **kwparameters).evaluate(0)
  File "/usr/local/lib/python3.6/dist-packages/py2neo/database/work.py", line 127, in run
    readonly=self.readonly)
  File "/usr/local/lib/python3.6/dist-packages/py2neo/client/__init__.py", line 1248, in auto_run
    cx = self.acquire(graph_name, readonly)
  File "/usr/local/lib/python3.6/dist-packages/py2neo/client/__init__.py", line 1075, in acquire
    cx = pool.acquire(force_reset=force_reset)
  File "/usr/local/lib/python3.6/dist-packages/py2neo/client/__init__.py", line 749, in acquire
    cx = self.connect()
  File "/usr/local/lib/python3.6/dist-packages/py2neo/client/__init__.py", line 702, in connect
    self._bytes_sent += cx.bytes_sent
  File "/usr/local/lib/python3.6/dist-packages/py2neo/client/__init__.py", line 184, in bytes_sent
    raise NotImplementedError
NotImplementedError

During handling of the above exception, another exception occurred:

Traceback (most recent call last):
  File "/usr/local/lib/python3.6/dist-packages/werkzeug/serving.py", line 302, in run_wsgi
    execute(self.server.app)
  File "/usr/local/lib/python3.6/dist-packages/werkzeug/serving.py", line 290, in execute
    application_iter = app(environ, start_response)
  File "/usr/local/lib/python3.6/dist-packages/flask/app.py", line 2309, in __call__
    return self.wsgi_app(environ, start_response)
  File "/usr/local/lib/python3.6/dist-packages/flask/app.py", line 2295, in wsgi_app
    response = self.handle_exception(e)
  File "/usr/local/lib/python3.6/dist-packages/flask/app.py", line 1748, in handle_exception
    return self.finalize_request(handler(e), from_error_handler=True)
  File "/home/cartos.di.uminho.pt/LEI/cartos-master/app/base/routes.py", line 274, in internal_error
    return render_template('errors/page_500.html'), 500
  File "/usr/local/lib/python3.6/dist-packages/flask/templating.py", line 133, in render_template
    ctx.app.update_template_context(context)
  File "/usr/local/lib/python3.6/dist-packages/flask/app.py", line 792, in update_template_context
    context.update(func())
  File "/usr/local/lib/python3.6/dist-packages/flask_login/utils.py", line 379, in _user_context_processor
    return dict(current_user=_get_user())
  File "/usr/local/lib/python3.6/dist-packages/flask_login/utils.py", line 346, in _get_user
    current_app.login_manager._load_user()
  File "/usr/local/lib/python3.6/dist-packages/flask_login/login_manager.py", line 303, in _load_user
    "Missing user_loader or request_loader. Refer to "
Exception: Missing user_loader or request_loader. Refer to http://flask-login.readthedocs.io/#how-it-works for more info.
127.0.0.1 - - [25/Apr/2021 22:05:28] "POST /login HTTP/1.1" 200 -
127.0.0.1 - - [25/Apr/2021 22:05:38] "POST /login HTTP/1.1" 200 -
127.0.0.1 - - [25/Apr/2021 22:05:42] "POST /login HTTP/1.1" 200 -
127.0.0.1 - - [25/Apr/2021 22:05:43] "GET /users/users?nome=xkstr HTTP/1.1" 401 -
127.0.0.1 - - [25/Apr/2021 22:05:43] "GET /folios/folios?nome=xkstr HTTP/1.1" 404 -
127.0.0.1 - - [25/Apr/2021 22:05:43] "GET /users/foto/xkstr HTTP/1.1" 200 -
127.0.0.1 - - [25/Apr/2021 22:05:43] "GET /users/foto/xkstr?seed=1619384742921 HTTP/1.1" 200 -
127.0.0.1 - - [25/Apr/2021 22:05:56] "GET /users/users?nome=admin HTTP/1.1" 200 -
127.0.0.1 - - [25/Apr/2021 22:05:57] "GET /users/foto/xkstr?seed=1619384756813 HTTP/1.1" 200 -
127.0.0.1 - - [25/Apr/2021 22:06:06] "GET /analise/foliosnames HTTP/1.1" 200 -
127.0.0.1 - - [25/Apr/2021 22:06:06] "GET /users/foto/xkstr?seed=1619384766110 HTTP/1.1" 200 -
127.0.0.1 - - [25/Apr/2021 22:06:09] "GET /folios/folios?nome=xkstr HTTP/1.1" 404 -
127.0.0.1 - - [25/Apr/2021 22:06:09] "GET /users/foto/xkstr?seed=1619384769670 HTTP/1.1" 200 -
127.0.0.1 - - [25/Apr/2021 22:08:06] "GET /analise/foliosnames HTTP/1.1" 200 -
127.0.0.1 - - [25/Apr/2021 22:08:16] "POST /login HTTP/1.1" 200 -
127.0.0.1 - - [25/Apr/2021 22:08:24] "POST /login HTTP/1.1" 200 -
